[2024-05-16 09:26:22,975: INFO: main: This is a test log message]
[2024-05-16 14:21:38,432: INFO: main: >>>>>> stage Data Ingestion stage started <<<<<<]
[2024-05-16 14:21:38,437: INFO: common: yaml file: config\config.yaml loaded successfully]
[2024-05-16 14:21:38,438: INFO: common: yaml file: params.yaml loaded successfully]
[2024-05-16 14:21:38,438: ERROR: main: yaml file is empty]
Traceback (most recent call last):
  File "D:\Projects\Stock_Market_Predictor_ETE\src\stock_predictor\utils\common.py", line 31, in read_yaml
    return ConfigBox(content)
           ^^^^^^^^^^^^^^^^^^
  File "C:\Users\pr141\PycharmProjects\pythonProject\venv\Lib\site-packages\box\box.py", line 259, in __init__
    raise BoxValueError("First argument must be mapping or iterable")
box.exceptions.BoxValueError: First argument must be mapping or iterable

During handling of the above exception, another exception occurred:

Traceback (most recent call last):
  File "D:\Projects\Stock_Market_Predictor_ETE\main.py", line 10, in <module>
    obj.main()
  File "D:\Projects\Stock_Market_Predictor_ETE\src\stock_predictor\pipeline\stage_01_data_ingestion.py", line 14, in main
    config = ConfigurationManager()
             ^^^^^^^^^^^^^^^^^^^^^^
  File "D:\Projects\Stock_Market_Predictor_ETE\src\stock_predictor\config\configuration.py", line 13, in __init__
    self.params = read_yaml(params_filepath)
                  ^^^^^^^^^^^^^^^^^^^^^^^^^^
  File "C:\Users\pr141\PycharmProjects\pythonProject\venv\Lib\site-packages\ensure\main.py", line 872, in __call__
    return_val = self.f(*args, **kwargs)
                 ^^^^^^^^^^^^^^^^^^^^^^^
  File "D:\Projects\Stock_Market_Predictor_ETE\src\stock_predictor\utils\common.py", line 33, in read_yaml
    raise ValueError("yaml file is empty")
ValueError: yaml file is empty
[2024-05-16 14:22:02,923: INFO: main: >>>>>> stage Data Ingestion stage started <<<<<<]
[2024-05-16 14:22:02,925: INFO: common: yaml file: config\config.yaml loaded successfully]
[2024-05-16 14:22:02,926: INFO: common: yaml file: params.yaml loaded successfully]
[2024-05-16 14:22:02,927: INFO: common: yaml file: schema.yaml loaded successfully]
[2024-05-16 14:22:02,927: INFO: common: created directory at: artifacts]
[2024-05-16 14:22:02,927: INFO: common: created directory at: artifacts/data_ingestion]
[2024-05-16 14:22:02,928: ERROR: main: name 'Path' is not defined]
Traceback (most recent call last):
  File "D:\Projects\Stock_Market_Predictor_ETE\main.py", line 10, in <module>
    obj.main()
  File "D:\Projects\Stock_Market_Predictor_ETE\src\stock_predictor\pipeline\stage_01_data_ingestion.py", line 17, in main
    data_ingestion.download_data()
  File "D:\Projects\Stock_Market_Predictor_ETE\src\stock_predictor\components\data_ingestion.py", line 20, in download_data
    logger.info(f"File already exists of size: {get_size(Path(self.config.local_data_file))}")
                                                         ^^^^
NameError: name 'Path' is not defined
[2024-05-16 14:23:12,974: INFO: main: >>>>>> stage Data Ingestion stage started <<<<<<]
[2024-05-16 14:23:12,975: INFO: common: yaml file: config\config.yaml loaded successfully]
[2024-05-16 14:23:12,975: INFO: common: yaml file: params.yaml loaded successfully]
[2024-05-16 14:23:12,976: INFO: common: yaml file: schema.yaml loaded successfully]
[2024-05-16 14:23:12,976: INFO: common: created directory at: artifacts]
[2024-05-16 14:23:12,976: INFO: common: created directory at: artifacts/data_ingestion]
[2024-05-16 14:23:12,976: ERROR: main: [WinError 2] The system cannot find the file specified: 'artifacts\\data_ingestion\\data.zip']
Traceback (most recent call last):
  File "D:\Projects\Stock_Market_Predictor_ETE\main.py", line 10, in <module>
    obj.main()
  File "D:\Projects\Stock_Market_Predictor_ETE\src\stock_predictor\pipeline\stage_01_data_ingestion.py", line 17, in main
    data_ingestion.download_data()
  File "D:\Projects\Stock_Market_Predictor_ETE\src\stock_predictor\components\data_ingestion.py", line 21, in download_data
    logger.info(f"File already exists of size: {get_size(Path(self.config.local_data_file))}")
                                                ^^^^^^^^^^^^^^^^^^^^^^^^^^^^^^^^^^^^^^^^^^^
  File "C:\Users\pr141\PycharmProjects\pythonProject\venv\Lib\site-packages\ensure\main.py", line 872, in __call__
    return_val = self.f(*args, **kwargs)
                 ^^^^^^^^^^^^^^^^^^^^^^^
  File "D:\Projects\Stock_Market_Predictor_ETE\src\stock_predictor\utils\common.py", line 120, in get_size
    size_in_kb = round(os.path.getsize(path) / 1024)
                       ^^^^^^^^^^^^^^^^^^^^^
  File "<frozen genericpath>", line 62, in getsize
FileNotFoundError: [WinError 2] The system cannot find the file specified: 'artifacts\\data_ingestion\\data.zip'
[2024-05-16 14:29:19,152: INFO: main: >>>>>> stage Data Ingestion stage started <<<<<<]
[2024-05-16 14:29:19,152: INFO: common: yaml file: config\config.yaml loaded successfully]
[2024-05-16 14:29:19,153: INFO: common: yaml file: params.yaml loaded successfully]
[2024-05-16 14:29:19,154: INFO: common: yaml file: schema.yaml loaded successfully]
[2024-05-16 14:29:19,154: ERROR: main: "'ConfigBox' object has no attribute 'artifacts_roots'"]
Traceback (most recent call last):
  File "C:\Users\pr141\PycharmProjects\pythonProject\venv\Lib\site-packages\box\box.py", line 503, in __getitem__
    return super().__getitem__(item)
           ^^^^^^^^^^^^^^^^^^^^^^^^^
KeyError: 'artifacts_roots'

The above exception was the direct cause of the following exception:

Traceback (most recent call last):
  File "C:\Users\pr141\PycharmProjects\pythonProject\venv\Lib\site-packages\box\box.py", line 536, in __getattr__
    value = self.__getitem__(item, _ignore_default=True)
            ^^^^^^^^^^^^^^^^^^^^^^^^^^^^^^^^^^^^^^^^^^^^
  File "C:\Users\pr141\PycharmProjects\pythonProject\venv\Lib\site-packages\box\box.py", line 524, in __getitem__
    raise BoxKeyError(str(err)) from _exception_cause(err)
box.exceptions.BoxKeyError: "'artifacts_roots'"

During handling of the above exception, another exception occurred:

Traceback (most recent call last):
  File "C:\Users\pr141\PycharmProjects\pythonProject\venv\Lib\site-packages\box\box.py", line 538, in __getattr__
    value = object.__getattribute__(self, item)
            ^^^^^^^^^^^^^^^^^^^^^^^^^^^^^^^^^^^
AttributeError: 'ConfigBox' object has no attribute 'artifacts_roots'. Did you mean: 'artifacts_root'?

The above exception was the direct cause of the following exception:

Traceback (most recent call last):
  File "C:\Users\pr141\PycharmProjects\pythonProject\venv\Lib\site-packages\box\config_box.py", line 28, in __getattr__
    return super().__getattr__(item)
           ^^^^^^^^^^^^^^^^^^^^^^^^^
  File "C:\Users\pr141\PycharmProjects\pythonProject\venv\Lib\site-packages\box\box.py", line 552, in __getattr__
    raise BoxKeyError(str(err)) from _exception_cause(err)
box.exceptions.BoxKeyError: "'ConfigBox' object has no attribute 'artifacts_roots'"

During handling of the above exception, another exception occurred:

Traceback (most recent call last):
  File "C:\Users\pr141\PycharmProjects\pythonProject\venv\Lib\site-packages\box\box.py", line 503, in __getitem__
    return super().__getitem__(item)
           ^^^^^^^^^^^^^^^^^^^^^^^^^
KeyError: 'artifacts_roots'

The above exception was the direct cause of the following exception:

Traceback (most recent call last):
  File "C:\Users\pr141\PycharmProjects\pythonProject\venv\Lib\site-packages\box\box.py", line 536, in __getattr__
    value = self.__getitem__(item, _ignore_default=True)
            ^^^^^^^^^^^^^^^^^^^^^^^^^^^^^^^^^^^^^^^^^^^^
  File "C:\Users\pr141\PycharmProjects\pythonProject\venv\Lib\site-packages\box\box.py", line 524, in __getitem__
    raise BoxKeyError(str(err)) from _exception_cause(err)
box.exceptions.BoxKeyError: "'artifacts_roots'"

During handling of the above exception, another exception occurred:

Traceback (most recent call last):
  File "C:\Users\pr141\PycharmProjects\pythonProject\venv\Lib\site-packages\box\box.py", line 538, in __getattr__
    value = object.__getattribute__(self, item)
            ^^^^^^^^^^^^^^^^^^^^^^^^^^^^^^^^^^^
AttributeError: 'ConfigBox' object has no attribute 'artifacts_roots'. Did you mean: 'artifacts_root'?

The above exception was the direct cause of the following exception:

Traceback (most recent call last):
  File "D:\Projects\Stock_Market_Predictor_ETE\main.py", line 10, in <module>
    obj.main()
  File "D:\Projects\Stock_Market_Predictor_ETE\src\stock_predictor\pipeline\stage_01_data_ingestion.py", line 14, in main
    config = ConfigurationManager()
             ^^^^^^^^^^^^^^^^^^^^^^
  File "D:\Projects\Stock_Market_Predictor_ETE\src\stock_predictor\config\configuration.py", line 16, in __init__
    create_directories([self.config.artifacts_roots])
                        ^^^^^^^^^^^^^^^^^^^^^^^^^^^
  File "C:\Users\pr141\PycharmProjects\pythonProject\venv\Lib\site-packages\box\config_box.py", line 30, in __getattr__
    return super().__getattr__(item.lower())
           ^^^^^^^^^^^^^^^^^^^^^^^^^^^^^^^^^
  File "C:\Users\pr141\PycharmProjects\pythonProject\venv\Lib\site-packages\box\box.py", line 552, in __getattr__
    raise BoxKeyError(str(err)) from _exception_cause(err)
box.exceptions.BoxKeyError: "'ConfigBox' object has no attribute 'artifacts_roots'". Did you mean: 'artifacts_root'?
[2024-05-16 14:29:43,794: INFO: main: >>>>>> stage Data Ingestion stage started <<<<<<]
[2024-05-16 14:29:43,795: INFO: common: yaml file: config\config.yaml loaded successfully]
[2024-05-16 14:29:43,796: INFO: common: yaml file: params.yaml loaded successfully]
[2024-05-16 14:29:43,796: INFO: common: yaml file: schema.yaml loaded successfully]
[2024-05-16 14:29:43,797: ERROR: main: "'ConfigBox' object has no attribute 'artifacts_roots'"]
Traceback (most recent call last):
  File "C:\Users\pr141\PycharmProjects\pythonProject\venv\Lib\site-packages\box\box.py", line 503, in __getitem__
    return super().__getitem__(item)
           ^^^^^^^^^^^^^^^^^^^^^^^^^
KeyError: 'artifacts_roots'

The above exception was the direct cause of the following exception:

Traceback (most recent call last):
  File "C:\Users\pr141\PycharmProjects\pythonProject\venv\Lib\site-packages\box\box.py", line 536, in __getattr__
    value = self.__getitem__(item, _ignore_default=True)
            ^^^^^^^^^^^^^^^^^^^^^^^^^^^^^^^^^^^^^^^^^^^^
  File "C:\Users\pr141\PycharmProjects\pythonProject\venv\Lib\site-packages\box\box.py", line 524, in __getitem__
    raise BoxKeyError(str(err)) from _exception_cause(err)
box.exceptions.BoxKeyError: "'artifacts_roots'"

During handling of the above exception, another exception occurred:

Traceback (most recent call last):
  File "C:\Users\pr141\PycharmProjects\pythonProject\venv\Lib\site-packages\box\box.py", line 538, in __getattr__
    value = object.__getattribute__(self, item)
            ^^^^^^^^^^^^^^^^^^^^^^^^^^^^^^^^^^^
AttributeError: 'ConfigBox' object has no attribute 'artifacts_roots'. Did you mean: 'artifacts_root'?

The above exception was the direct cause of the following exception:

Traceback (most recent call last):
  File "C:\Users\pr141\PycharmProjects\pythonProject\venv\Lib\site-packages\box\config_box.py", line 28, in __getattr__
    return super().__getattr__(item)
           ^^^^^^^^^^^^^^^^^^^^^^^^^
  File "C:\Users\pr141\PycharmProjects\pythonProject\venv\Lib\site-packages\box\box.py", line 552, in __getattr__
    raise BoxKeyError(str(err)) from _exception_cause(err)
box.exceptions.BoxKeyError: "'ConfigBox' object has no attribute 'artifacts_roots'"

During handling of the above exception, another exception occurred:

Traceback (most recent call last):
  File "C:\Users\pr141\PycharmProjects\pythonProject\venv\Lib\site-packages\box\box.py", line 503, in __getitem__
    return super().__getitem__(item)
           ^^^^^^^^^^^^^^^^^^^^^^^^^
KeyError: 'artifacts_roots'

The above exception was the direct cause of the following exception:

Traceback (most recent call last):
  File "C:\Users\pr141\PycharmProjects\pythonProject\venv\Lib\site-packages\box\box.py", line 536, in __getattr__
    value = self.__getitem__(item, _ignore_default=True)
            ^^^^^^^^^^^^^^^^^^^^^^^^^^^^^^^^^^^^^^^^^^^^
  File "C:\Users\pr141\PycharmProjects\pythonProject\venv\Lib\site-packages\box\box.py", line 524, in __getitem__
    raise BoxKeyError(str(err)) from _exception_cause(err)
box.exceptions.BoxKeyError: "'artifacts_roots'"

During handling of the above exception, another exception occurred:

Traceback (most recent call last):
  File "C:\Users\pr141\PycharmProjects\pythonProject\venv\Lib\site-packages\box\box.py", line 538, in __getattr__
    value = object.__getattribute__(self, item)
            ^^^^^^^^^^^^^^^^^^^^^^^^^^^^^^^^^^^
AttributeError: 'ConfigBox' object has no attribute 'artifacts_roots'. Did you mean: 'artifacts_root'?

The above exception was the direct cause of the following exception:

Traceback (most recent call last):
  File "D:\Projects\Stock_Market_Predictor_ETE\main.py", line 10, in <module>
    obj.main()
  File "D:\Projects\Stock_Market_Predictor_ETE\src\stock_predictor\pipeline\stage_01_data_ingestion.py", line 14, in main
    config = ConfigurationManager()
             ^^^^^^^^^^^^^^^^^^^^^^
  File "D:\Projects\Stock_Market_Predictor_ETE\src\stock_predictor\config\configuration.py", line 16, in __init__
    create_directories([self.config.artifacts_roots])
                        ^^^^^^^^^^^^^^^^^^^^^^^^^^^
  File "C:\Users\pr141\PycharmProjects\pythonProject\venv\Lib\site-packages\box\config_box.py", line 30, in __getattr__
    return super().__getattr__(item.lower())
           ^^^^^^^^^^^^^^^^^^^^^^^^^^^^^^^^^
  File "C:\Users\pr141\PycharmProjects\pythonProject\venv\Lib\site-packages\box\box.py", line 552, in __getattr__
    raise BoxKeyError(str(err)) from _exception_cause(err)
box.exceptions.BoxKeyError: "'ConfigBox' object has no attribute 'artifacts_roots'". Did you mean: 'artifacts_root'?
[2024-05-16 14:30:20,239: INFO: main: >>>>>> stage Data Ingestion stage started <<<<<<]
[2024-05-16 14:30:20,240: INFO: common: yaml file: config\config.yaml loaded successfully]
[2024-05-16 14:30:20,241: INFO: common: yaml file: params.yaml loaded successfully]
[2024-05-16 14:30:20,241: INFO: common: yaml file: schema.yaml loaded successfully]
[2024-05-16 14:30:20,241: INFO: common: created directory at: artifacts]
[2024-05-16 14:30:20,242: INFO: common: created directory at: artifacts/data_ingestion]
[2024-05-16 14:30:25,305: INFO: data_ingestion: artifacts/data_ingestion/data.zip download! with following info: 
Connection: close
Content-Length: 300940
Cache-Control: max-age=300
Content-Security-Policy: default-src 'none'; style-src 'unsafe-inline'; sandbox
Content-Type: application/zip
ETag: "d076672f1746d4eb167a00b3b2c7f6458cc7ecfa4fa23f72f3f26faa16aaae43"
Strict-Transport-Security: max-age=31536000
X-Content-Type-Options: nosniff
X-Frame-Options: deny
X-XSS-Protection: 1; mode=block
X-GitHub-Request-Id: 3FF8:0957:8E45D:C04E6:6645CB26
Accept-Ranges: bytes
Date: Thu, 16 May 2024 09:00:23 GMT
Via: 1.1 varnish
X-Served-By: cache-maa10249-MAA
X-Cache: MISS
X-Cache-Hits: 0
X-Timer: S1715850023.447134,VS0,VE312
Vary: Authorization,Accept-Encoding,Origin
Access-Control-Allow-Origin: *
Cross-Origin-Resource-Policy: cross-origin
X-Fastly-Request-ID: b306bba45d9fd37df4cb24d9ebbd8ff3a00246d8
Expires: Thu, 16 May 2024 09:05:23 GMT
Source-Age: 0

]
[2024-05-16 14:30:25,319: INFO: main: >>>>>> stage Data Ingestion stage completed <<<<<<

x==========x]
[2024-05-16 20:11:19,172: INFO: main: >>>>>> stage Data Ingestion stage started <<<<<<]
[2024-05-16 20:11:19,173: INFO: common: yaml file: config\config.yaml loaded successfully]
[2024-05-16 20:11:19,175: INFO: common: yaml file: params.yaml loaded successfully]
[2024-05-16 20:11:19,176: INFO: common: yaml file: schema.yaml loaded successfully]
[2024-05-16 20:11:19,176: INFO: common: created directory at: artifacts]
[2024-05-16 20:11:19,177: INFO: common: created directory at: artifacts/data_ingestion]
[2024-05-16 20:11:19,177: INFO: data_ingestion: file already exists of size: ~ 294 KB]
[2024-05-16 20:11:19,185: INFO: main: >>>>>> stage Data Ingestion stage completed <<<<<<

x==========x]
[2024-05-16 20:11:19,186: INFO: main: >>>>>> stage Data Validation stage started <<<<<<]
[2024-05-16 20:11:19,187: INFO: common: yaml file: config\config.yaml loaded successfully]
[2024-05-16 20:11:19,188: INFO: common: yaml file: params.yaml loaded successfully]
[2024-05-16 20:11:19,189: INFO: common: yaml file: schema.yaml loaded successfully]
[2024-05-16 20:11:19,190: INFO: common: created directory at: artifacts]
[2024-05-16 20:11:19,190: ERROR: main: "'ConfigBox' object has no attribute 'data_validation'"]
Traceback (most recent call last):
  File "C:\Users\pr141\PycharmProjects\pythonProject\venv\Lib\site-packages\box\box.py", line 503, in __getitem__
    return super().__getitem__(item)
           ^^^^^^^^^^^^^^^^^^^^^^^^^
KeyError: 'data_validation'

The above exception was the direct cause of the following exception:

Traceback (most recent call last):
  File "C:\Users\pr141\PycharmProjects\pythonProject\venv\Lib\site-packages\box\box.py", line 536, in __getattr__
    value = self.__getitem__(item, _ignore_default=True)
            ^^^^^^^^^^^^^^^^^^^^^^^^^^^^^^^^^^^^^^^^^^^^
  File "C:\Users\pr141\PycharmProjects\pythonProject\venv\Lib\site-packages\box\box.py", line 524, in __getitem__
    raise BoxKeyError(str(err)) from _exception_cause(err)
box.exceptions.BoxKeyError: "'data_validation'"

During handling of the above exception, another exception occurred:

Traceback (most recent call last):
  File "C:\Users\pr141\PycharmProjects\pythonProject\venv\Lib\site-packages\box\box.py", line 538, in __getattr__
    value = object.__getattribute__(self, item)
            ^^^^^^^^^^^^^^^^^^^^^^^^^^^^^^^^^^^
AttributeError: 'ConfigBox' object has no attribute 'data_validation'

The above exception was the direct cause of the following exception:

Traceback (most recent call last):
  File "C:\Users\pr141\PycharmProjects\pythonProject\venv\Lib\site-packages\box\config_box.py", line 28, in __getattr__
    return super().__getattr__(item)
           ^^^^^^^^^^^^^^^^^^^^^^^^^
  File "C:\Users\pr141\PycharmProjects\pythonProject\venv\Lib\site-packages\box\box.py", line 552, in __getattr__
    raise BoxKeyError(str(err)) from _exception_cause(err)
box.exceptions.BoxKeyError: "'ConfigBox' object has no attribute 'data_validation'"

During handling of the above exception, another exception occurred:

Traceback (most recent call last):
  File "C:\Users\pr141\PycharmProjects\pythonProject\venv\Lib\site-packages\box\box.py", line 503, in __getitem__
    return super().__getitem__(item)
           ^^^^^^^^^^^^^^^^^^^^^^^^^
KeyError: 'data_validation'

The above exception was the direct cause of the following exception:

Traceback (most recent call last):
  File "C:\Users\pr141\PycharmProjects\pythonProject\venv\Lib\site-packages\box\box.py", line 536, in __getattr__
    value = self.__getitem__(item, _ignore_default=True)
            ^^^^^^^^^^^^^^^^^^^^^^^^^^^^^^^^^^^^^^^^^^^^
  File "C:\Users\pr141\PycharmProjects\pythonProject\venv\Lib\site-packages\box\box.py", line 524, in __getitem__
    raise BoxKeyError(str(err)) from _exception_cause(err)
box.exceptions.BoxKeyError: "'data_validation'"

During handling of the above exception, another exception occurred:

Traceback (most recent call last):
  File "C:\Users\pr141\PycharmProjects\pythonProject\venv\Lib\site-packages\box\box.py", line 538, in __getattr__
    value = object.__getattribute__(self, item)
            ^^^^^^^^^^^^^^^^^^^^^^^^^^^^^^^^^^^
AttributeError: 'ConfigBox' object has no attribute 'data_validation'

The above exception was the direct cause of the following exception:

Traceback (most recent call last):
  File "D:\Projects\Stock_Market_Predictor_ETE\main.py", line 23, in <module>
    obj.main()
  File "D:\Projects\Stock_Market_Predictor_ETE\src\stock_predictor\pipeline\stage_02_data_validation.py", line 15, in main
    data_ingestion_config = config.get_data_validation_config()
                            ^^^^^^^^^^^^^^^^^^^^^^^^^^^^^^^^^^^
  File "D:\Projects\Stock_Market_Predictor_ETE\src\stock_predictor\config\configuration.py", line 33, in get_data_validation_config
    config = self.config.data_validation
             ^^^^^^^^^^^^^^^^^^^^^^^^^^^
  File "C:\Users\pr141\PycharmProjects\pythonProject\venv\Lib\site-packages\box\config_box.py", line 30, in __getattr__
    return super().__getattr__(item.lower())
           ^^^^^^^^^^^^^^^^^^^^^^^^^^^^^^^^^
  File "C:\Users\pr141\PycharmProjects\pythonProject\venv\Lib\site-packages\box\box.py", line 552, in __getattr__
    raise BoxKeyError(str(err)) from _exception_cause(err)
box.exceptions.BoxKeyError: "'ConfigBox' object has no attribute 'data_validation'"
[2024-05-17 19:59:36,129: INFO: main: >>>>>> stage Data Ingestion stage started <<<<<<]
[2024-05-17 19:59:36,131: INFO: common: yaml file: config\config.yaml loaded successfully]
[2024-05-17 19:59:36,134: INFO: common: yaml file: params.yaml loaded successfully]
[2024-05-17 19:59:36,142: INFO: common: yaml file: schema.yaml loaded successfully]
[2024-05-17 19:59:36,143: INFO: common: created directory at: artifacts]
[2024-05-17 19:59:36,144: INFO: common: created directory at: artifacts/data_ingestion]
[2024-05-17 19:59:36,144: INFO: data_ingestion: file already exists of size: ~ 294 KB]
[2024-05-17 19:59:36,158: INFO: main: >>>>>> stage Data Ingestion stage completed <<<<<<

x==========x]
[2024-05-17 19:59:36,158: INFO: main: >>>>>> stage Data Validation stage started <<<<<<]
[2024-05-17 19:59:36,159: INFO: common: yaml file: config\config.yaml loaded successfully]
[2024-05-17 19:59:36,160: INFO: common: yaml file: params.yaml loaded successfully]
[2024-05-17 19:59:36,161: INFO: common: yaml file: schema.yaml loaded successfully]
[2024-05-17 19:59:36,161: INFO: common: created directory at: artifacts]
[2024-05-17 19:59:36,162: ERROR: main: "'ConfigBox' object has no attribute 'data_validation'"]
Traceback (most recent call last):
  File "C:\Users\pr141\PycharmProjects\pythonProject\venv\Lib\site-packages\box\box.py", line 503, in __getitem__
    return super().__getitem__(item)
           ^^^^^^^^^^^^^^^^^^^^^^^^^
KeyError: 'data_validation'

The above exception was the direct cause of the following exception:

Traceback (most recent call last):
  File "C:\Users\pr141\PycharmProjects\pythonProject\venv\Lib\site-packages\box\box.py", line 536, in __getattr__
    value = self.__getitem__(item, _ignore_default=True)
            ^^^^^^^^^^^^^^^^^^^^^^^^^^^^^^^^^^^^^^^^^^^^
  File "C:\Users\pr141\PycharmProjects\pythonProject\venv\Lib\site-packages\box\box.py", line 524, in __getitem__
    raise BoxKeyError(str(err)) from _exception_cause(err)
box.exceptions.BoxKeyError: "'data_validation'"

During handling of the above exception, another exception occurred:

Traceback (most recent call last):
  File "C:\Users\pr141\PycharmProjects\pythonProject\venv\Lib\site-packages\box\box.py", line 538, in __getattr__
    value = object.__getattribute__(self, item)
            ^^^^^^^^^^^^^^^^^^^^^^^^^^^^^^^^^^^
AttributeError: 'ConfigBox' object has no attribute 'data_validation'

The above exception was the direct cause of the following exception:

Traceback (most recent call last):
  File "C:\Users\pr141\PycharmProjects\pythonProject\venv\Lib\site-packages\box\config_box.py", line 28, in __getattr__
    return super().__getattr__(item)
           ^^^^^^^^^^^^^^^^^^^^^^^^^
  File "C:\Users\pr141\PycharmProjects\pythonProject\venv\Lib\site-packages\box\box.py", line 552, in __getattr__
    raise BoxKeyError(str(err)) from _exception_cause(err)
box.exceptions.BoxKeyError: "'ConfigBox' object has no attribute 'data_validation'"

During handling of the above exception, another exception occurred:

Traceback (most recent call last):
  File "C:\Users\pr141\PycharmProjects\pythonProject\venv\Lib\site-packages\box\box.py", line 503, in __getitem__
    return super().__getitem__(item)
           ^^^^^^^^^^^^^^^^^^^^^^^^^
KeyError: 'data_validation'

The above exception was the direct cause of the following exception:

Traceback (most recent call last):
  File "C:\Users\pr141\PycharmProjects\pythonProject\venv\Lib\site-packages\box\box.py", line 536, in __getattr__
    value = self.__getitem__(item, _ignore_default=True)
            ^^^^^^^^^^^^^^^^^^^^^^^^^^^^^^^^^^^^^^^^^^^^
  File "C:\Users\pr141\PycharmProjects\pythonProject\venv\Lib\site-packages\box\box.py", line 524, in __getitem__
    raise BoxKeyError(str(err)) from _exception_cause(err)
box.exceptions.BoxKeyError: "'data_validation'"

During handling of the above exception, another exception occurred:

Traceback (most recent call last):
  File "C:\Users\pr141\PycharmProjects\pythonProject\venv\Lib\site-packages\box\box.py", line 538, in __getattr__
    value = object.__getattribute__(self, item)
            ^^^^^^^^^^^^^^^^^^^^^^^^^^^^^^^^^^^
AttributeError: 'ConfigBox' object has no attribute 'data_validation'

The above exception was the direct cause of the following exception:

Traceback (most recent call last):
  File "D:\Projects\Stock_Market_Predictor_ETE\main.py", line 23, in <module>
    obj.main()
  File "D:\Projects\Stock_Market_Predictor_ETE\src\stock_predictor\pipeline\stage_02_data_validation.py", line 15, in main
    data_ingestion_config = config.get_data_validation_config()
                            ^^^^^^^^^^^^^^^^^^^^^^^^^^^^^^^^^^^
  File "D:\Projects\Stock_Market_Predictor_ETE\src\stock_predictor\config\configuration.py", line 33, in get_data_validation_config
    config = self.config.data_validation
             ^^^^^^^^^^^^^^^^^^^^^^^^^^^
  File "C:\Users\pr141\PycharmProjects\pythonProject\venv\Lib\site-packages\box\config_box.py", line 30, in __getattr__
    return super().__getattr__(item.lower())
           ^^^^^^^^^^^^^^^^^^^^^^^^^^^^^^^^^
  File "C:\Users\pr141\PycharmProjects\pythonProject\venv\Lib\site-packages\box\box.py", line 552, in __getattr__
    raise BoxKeyError(str(err)) from _exception_cause(err)
box.exceptions.BoxKeyError: "'ConfigBox' object has no attribute 'data_validation'"
[2024-05-17 20:11:11,529: INFO: main: >>>>>> stage Data Ingestion stage started <<<<<<]
[2024-05-17 20:11:11,530: INFO: common: yaml file: config\config.yaml loaded successfully]
[2024-05-17 20:11:11,531: INFO: common: yaml file: params.yaml loaded successfully]
[2024-05-17 20:11:11,532: INFO: common: yaml file: schema.yaml loaded successfully]
[2024-05-17 20:11:11,532: INFO: common: created directory at: artifacts]
[2024-05-17 20:11:11,533: INFO: common: created directory at: artifacts/data_ingestion]
[2024-05-17 20:11:12,904: INFO: data_ingestion: artifacts/data_ingestion/data.zip download! with following info: 
Connection: close
Content-Length: 300940
Cache-Control: max-age=300
Content-Security-Policy: default-src 'none'; style-src 'unsafe-inline'; sandbox
Content-Type: application/zip
ETag: "d076672f1746d4eb167a00b3b2c7f6458cc7ecfa4fa23f72f3f26faa16aaae43"
Strict-Transport-Security: max-age=31536000
X-Content-Type-Options: nosniff
X-Frame-Options: deny
X-XSS-Protection: 1; mode=block
X-GitHub-Request-Id: C200:08AE:1B8E21:23D424:66476C88
Accept-Ranges: bytes
Date: Fri, 17 May 2024 14:41:12 GMT
Via: 1.1 varnish
X-Served-By: cache-maa10248-MAA
X-Cache: MISS
X-Cache-Hits: 0
X-Timer: S1715956873.578743,VS0,VE307
Vary: Authorization,Accept-Encoding,Origin
Access-Control-Allow-Origin: *
Cross-Origin-Resource-Policy: cross-origin
X-Fastly-Request-ID: ee8dcf2e28cb0d9d11a3e782b20390e7717b8095
Expires: Fri, 17 May 2024 14:46:12 GMT
Source-Age: 0

]
[2024-05-17 20:11:12,919: INFO: main: >>>>>> stage Data Ingestion stage completed <<<<<<

x==========x]
[2024-05-17 20:11:12,919: INFO: main: >>>>>> stage Data Validation stage started <<<<<<]
[2024-05-17 20:11:12,920: INFO: common: yaml file: config\config.yaml loaded successfully]
[2024-05-17 20:11:12,920: INFO: common: yaml file: params.yaml loaded successfully]
[2024-05-17 20:11:12,922: INFO: common: yaml file: schema.yaml loaded successfully]
[2024-05-17 20:11:12,923: INFO: common: created directory at: artifacts]
[2024-05-17 20:11:12,923: ERROR: main: "'ConfigBox' object has no attribute 'data_validation'"]
Traceback (most recent call last):
  File "C:\Users\pr141\PycharmProjects\pythonProject\venv\Lib\site-packages\box\box.py", line 503, in __getitem__
    return super().__getitem__(item)
           ^^^^^^^^^^^^^^^^^^^^^^^^^
KeyError: 'data_validation'

The above exception was the direct cause of the following exception:

Traceback (most recent call last):
  File "C:\Users\pr141\PycharmProjects\pythonProject\venv\Lib\site-packages\box\box.py", line 536, in __getattr__
    value = self.__getitem__(item, _ignore_default=True)
            ^^^^^^^^^^^^^^^^^^^^^^^^^^^^^^^^^^^^^^^^^^^^
  File "C:\Users\pr141\PycharmProjects\pythonProject\venv\Lib\site-packages\box\box.py", line 524, in __getitem__
    raise BoxKeyError(str(err)) from _exception_cause(err)
box.exceptions.BoxKeyError: "'data_validation'"

During handling of the above exception, another exception occurred:

Traceback (most recent call last):
  File "C:\Users\pr141\PycharmProjects\pythonProject\venv\Lib\site-packages\box\box.py", line 538, in __getattr__
    value = object.__getattribute__(self, item)
            ^^^^^^^^^^^^^^^^^^^^^^^^^^^^^^^^^^^
AttributeError: 'ConfigBox' object has no attribute 'data_validation'

The above exception was the direct cause of the following exception:

Traceback (most recent call last):
  File "C:\Users\pr141\PycharmProjects\pythonProject\venv\Lib\site-packages\box\config_box.py", line 28, in __getattr__
    return super().__getattr__(item)
           ^^^^^^^^^^^^^^^^^^^^^^^^^
  File "C:\Users\pr141\PycharmProjects\pythonProject\venv\Lib\site-packages\box\box.py", line 552, in __getattr__
    raise BoxKeyError(str(err)) from _exception_cause(err)
box.exceptions.BoxKeyError: "'ConfigBox' object has no attribute 'data_validation'"

During handling of the above exception, another exception occurred:

Traceback (most recent call last):
  File "C:\Users\pr141\PycharmProjects\pythonProject\venv\Lib\site-packages\box\box.py", line 503, in __getitem__
    return super().__getitem__(item)
           ^^^^^^^^^^^^^^^^^^^^^^^^^
KeyError: 'data_validation'

The above exception was the direct cause of the following exception:

Traceback (most recent call last):
  File "C:\Users\pr141\PycharmProjects\pythonProject\venv\Lib\site-packages\box\box.py", line 536, in __getattr__
    value = self.__getitem__(item, _ignore_default=True)
            ^^^^^^^^^^^^^^^^^^^^^^^^^^^^^^^^^^^^^^^^^^^^
  File "C:\Users\pr141\PycharmProjects\pythonProject\venv\Lib\site-packages\box\box.py", line 524, in __getitem__
    raise BoxKeyError(str(err)) from _exception_cause(err)
box.exceptions.BoxKeyError: "'data_validation'"

During handling of the above exception, another exception occurred:

Traceback (most recent call last):
  File "C:\Users\pr141\PycharmProjects\pythonProject\venv\Lib\site-packages\box\box.py", line 538, in __getattr__
    value = object.__getattribute__(self, item)
            ^^^^^^^^^^^^^^^^^^^^^^^^^^^^^^^^^^^
AttributeError: 'ConfigBox' object has no attribute 'data_validation'

The above exception was the direct cause of the following exception:

Traceback (most recent call last):
  File "D:\Projects\Stock_Market_Predictor_ETE\main.py", line 23, in <module>
    obj.main()
  File "D:\Projects\Stock_Market_Predictor_ETE\src\stock_predictor\pipeline\stage_02_data_validation.py", line 15, in main
    data_ingestion_config = config.get_data_validation_config()
                            ^^^^^^^^^^^^^^^^^^^^^^^^^^^^^^^^^^^
  File "D:\Projects\Stock_Market_Predictor_ETE\src\stock_predictor\config\configuration.py", line 33, in get_data_validation_config
    config = self.config.data_validation
             ^^^^^^^^^^^^^^^^^^^^^^^^^^^
  File "C:\Users\pr141\PycharmProjects\pythonProject\venv\Lib\site-packages\box\config_box.py", line 30, in __getattr__
    return super().__getattr__(item.lower())
           ^^^^^^^^^^^^^^^^^^^^^^^^^^^^^^^^^
  File "C:\Users\pr141\PycharmProjects\pythonProject\venv\Lib\site-packages\box\box.py", line 552, in __getattr__
    raise BoxKeyError(str(err)) from _exception_cause(err)
box.exceptions.BoxKeyError: "'ConfigBox' object has no attribute 'data_validation'"
[2024-05-17 20:15:19,413: INFO: main: >>>>>> stage Data Ingestion stage started <<<<<<]
[2024-05-17 20:15:19,414: INFO: common: yaml file: config\config.yaml loaded successfully]
[2024-05-17 20:15:19,415: INFO: common: yaml file: params.yaml loaded successfully]
[2024-05-17 20:15:19,416: INFO: common: yaml file: schema.yaml loaded successfully]
[2024-05-17 20:15:19,416: INFO: common: created directory at: artifacts]
[2024-05-17 20:15:19,417: INFO: common: created directory at: artifacts/data_ingestion]
[2024-05-17 20:15:19,417: INFO: data_ingestion: file already exists of size: ~ 294 KB]
[2024-05-17 20:15:19,422: INFO: main: >>>>>> stage Data Ingestion stage completed <<<<<<

x==========x]
[2024-05-17 20:15:19,422: INFO: main: >>>>>> stage Data Validation stage started <<<<<<]
[2024-05-17 20:15:19,423: INFO: common: yaml file: config\config.yaml loaded successfully]
[2024-05-17 20:15:19,424: INFO: common: yaml file: params.yaml loaded successfully]
[2024-05-17 20:15:19,425: INFO: common: yaml file: schema.yaml loaded successfully]
[2024-05-17 20:15:19,425: INFO: common: created directory at: artifacts]
[2024-05-17 20:15:19,425: ERROR: main: "'ConfigBox' object has no attribute 'data_validation'"]
Traceback (most recent call last):
  File "C:\Users\pr141\PycharmProjects\pythonProject\venv\Lib\site-packages\box\box.py", line 503, in __getitem__
    return super().__getitem__(item)
           ^^^^^^^^^^^^^^^^^^^^^^^^^
KeyError: 'data_validation'

The above exception was the direct cause of the following exception:

Traceback (most recent call last):
  File "C:\Users\pr141\PycharmProjects\pythonProject\venv\Lib\site-packages\box\box.py", line 536, in __getattr__
    value = self.__getitem__(item, _ignore_default=True)
            ^^^^^^^^^^^^^^^^^^^^^^^^^^^^^^^^^^^^^^^^^^^^
  File "C:\Users\pr141\PycharmProjects\pythonProject\venv\Lib\site-packages\box\box.py", line 524, in __getitem__
    raise BoxKeyError(str(err)) from _exception_cause(err)
box.exceptions.BoxKeyError: "'data_validation'"

During handling of the above exception, another exception occurred:

Traceback (most recent call last):
  File "C:\Users\pr141\PycharmProjects\pythonProject\venv\Lib\site-packages\box\box.py", line 538, in __getattr__
    value = object.__getattribute__(self, item)
            ^^^^^^^^^^^^^^^^^^^^^^^^^^^^^^^^^^^
AttributeError: 'ConfigBox' object has no attribute 'data_validation'

The above exception was the direct cause of the following exception:

Traceback (most recent call last):
  File "C:\Users\pr141\PycharmProjects\pythonProject\venv\Lib\site-packages\box\config_box.py", line 28, in __getattr__
    return super().__getattr__(item)
           ^^^^^^^^^^^^^^^^^^^^^^^^^
  File "C:\Users\pr141\PycharmProjects\pythonProject\venv\Lib\site-packages\box\box.py", line 552, in __getattr__
    raise BoxKeyError(str(err)) from _exception_cause(err)
box.exceptions.BoxKeyError: "'ConfigBox' object has no attribute 'data_validation'"

During handling of the above exception, another exception occurred:

Traceback (most recent call last):
  File "C:\Users\pr141\PycharmProjects\pythonProject\venv\Lib\site-packages\box\box.py", line 503, in __getitem__
    return super().__getitem__(item)
           ^^^^^^^^^^^^^^^^^^^^^^^^^
KeyError: 'data_validation'

The above exception was the direct cause of the following exception:

Traceback (most recent call last):
  File "C:\Users\pr141\PycharmProjects\pythonProject\venv\Lib\site-packages\box\box.py", line 536, in __getattr__
    value = self.__getitem__(item, _ignore_default=True)
            ^^^^^^^^^^^^^^^^^^^^^^^^^^^^^^^^^^^^^^^^^^^^
  File "C:\Users\pr141\PycharmProjects\pythonProject\venv\Lib\site-packages\box\box.py", line 524, in __getitem__
    raise BoxKeyError(str(err)) from _exception_cause(err)
box.exceptions.BoxKeyError: "'data_validation'"

During handling of the above exception, another exception occurred:

Traceback (most recent call last):
  File "C:\Users\pr141\PycharmProjects\pythonProject\venv\Lib\site-packages\box\box.py", line 538, in __getattr__
    value = object.__getattribute__(self, item)
            ^^^^^^^^^^^^^^^^^^^^^^^^^^^^^^^^^^^
AttributeError: 'ConfigBox' object has no attribute 'data_validation'

The above exception was the direct cause of the following exception:

Traceback (most recent call last):
  File "D:\Projects\Stock_Market_Predictor_ETE\main.py", line 23, in <module>
    obj.main()
  File "D:\Projects\Stock_Market_Predictor_ETE\src\stock_predictor\pipeline\stage_02_data_validation.py", line 15, in main
    data_ingestion_config = config.get_data_validation_config()
                            ^^^^^^^^^^^^^^^^^^^^^^^^^^^^^^^^^^^
  File "D:\Projects\Stock_Market_Predictor_ETE\src\stock_predictor\config\configuration.py", line 33, in get_data_validation_config
    config = self.config.data_validation
             ^^^^^^^^^^^^^^^^^^^^^^^^^^^
  File "C:\Users\pr141\PycharmProjects\pythonProject\venv\Lib\site-packages\box\config_box.py", line 30, in __getattr__
    return super().__getattr__(item.lower())
           ^^^^^^^^^^^^^^^^^^^^^^^^^^^^^^^^^
  File "C:\Users\pr141\PycharmProjects\pythonProject\venv\Lib\site-packages\box\box.py", line 552, in __getattr__
    raise BoxKeyError(str(err)) from _exception_cause(err)
box.exceptions.BoxKeyError: "'ConfigBox' object has no attribute 'data_validation'"
[2024-05-17 20:21:29,248: INFO: main: >>>>>> stage Data Ingestion stage started <<<<<<]
[2024-05-17 20:21:29,248: ERROR: main: Argument path_to_yaml of type <class 'str'> to <function read_yaml at 0x000001B049DCAAC0> does not match annotation type <class 'pathlib.Path'>]
Traceback (most recent call last):
  File "D:\Projects\Stock_Market_Predictor_ETE\main.py", line 11, in <module>
    obj.main()
  File "D:\Projects\Stock_Market_Predictor_ETE\src\stock_predictor\pipeline\stage_01_data_ingestion.py", line 14, in main
    config = ConfigurationManager()
             ^^^^^^^^^^^^^^^^^^^^^^
  File "D:\Projects\Stock_Market_Predictor_ETE\src\stock_predictor\config\configuration.py", line 14, in __init__
    self.config = read_yaml(config_filepath)
                  ^^^^^^^^^^^^^^^^^^^^^^^^^^
  File "C:\Users\pr141\PycharmProjects\pythonProject\venv\Lib\site-packages\ensure\main.py", line 870, in __call__
    raise EnsureError(msg.format(arg=arg, f=self.f, t=templ, valt=type(value)))
ensure.main.EnsureError: Argument path_to_yaml of type <class 'str'> to <function read_yaml at 0x000001B049DCAAC0> does not match annotation type <class 'pathlib.Path'>
[2024-05-17 20:21:43,985: INFO: main: >>>>>> stage Data Ingestion stage started <<<<<<]
[2024-05-17 20:21:43,986: INFO: common: yaml file: config\config.yaml loaded successfully]
[2024-05-17 20:21:43,987: INFO: common: yaml file: params.yaml loaded successfully]
[2024-05-17 20:21:43,988: INFO: common: yaml file: schema.yaml loaded successfully]
[2024-05-17 20:21:43,988: INFO: common: created directory at: artifacts]
[2024-05-17 20:21:43,988: INFO: common: created directory at: artifacts/data_ingestion]
[2024-05-17 20:21:43,989: INFO: data_ingestion: file already exists of size: ~ 294 KB]
[2024-05-17 20:21:43,995: INFO: main: >>>>>> stage Data Ingestion stage completed <<<<<<

x==========x]
[2024-05-17 20:21:43,995: INFO: main: >>>>>> stage Data Validation stage started <<<<<<]
[2024-05-17 20:21:43,996: INFO: common: yaml file: config\config.yaml loaded successfully]
[2024-05-17 20:21:43,996: INFO: common: yaml file: params.yaml loaded successfully]
[2024-05-17 20:21:43,997: INFO: common: yaml file: schema.yaml loaded successfully]
[2024-05-17 20:21:43,998: INFO: common: created directory at: artifacts]
[2024-05-17 20:21:43,998: ERROR: main: "'ConfigBox' object has no attribute 'data_validation'"]
Traceback (most recent call last):
  File "C:\Users\pr141\PycharmProjects\pythonProject\venv\Lib\site-packages\box\box.py", line 503, in __getitem__
    return super().__getitem__(item)
           ^^^^^^^^^^^^^^^^^^^^^^^^^
KeyError: 'data_validation'

The above exception was the direct cause of the following exception:

Traceback (most recent call last):
  File "C:\Users\pr141\PycharmProjects\pythonProject\venv\Lib\site-packages\box\box.py", line 536, in __getattr__
    value = self.__getitem__(item, _ignore_default=True)
            ^^^^^^^^^^^^^^^^^^^^^^^^^^^^^^^^^^^^^^^^^^^^
  File "C:\Users\pr141\PycharmProjects\pythonProject\venv\Lib\site-packages\box\box.py", line 524, in __getitem__
    raise BoxKeyError(str(err)) from _exception_cause(err)
box.exceptions.BoxKeyError: "'data_validation'"

During handling of the above exception, another exception occurred:

Traceback (most recent call last):
  File "C:\Users\pr141\PycharmProjects\pythonProject\venv\Lib\site-packages\box\box.py", line 538, in __getattr__
    value = object.__getattribute__(self, item)
            ^^^^^^^^^^^^^^^^^^^^^^^^^^^^^^^^^^^
AttributeError: 'ConfigBox' object has no attribute 'data_validation'

The above exception was the direct cause of the following exception:

Traceback (most recent call last):
  File "C:\Users\pr141\PycharmProjects\pythonProject\venv\Lib\site-packages\box\config_box.py", line 28, in __getattr__
    return super().__getattr__(item)
           ^^^^^^^^^^^^^^^^^^^^^^^^^
  File "C:\Users\pr141\PycharmProjects\pythonProject\venv\Lib\site-packages\box\box.py", line 552, in __getattr__
    raise BoxKeyError(str(err)) from _exception_cause(err)
box.exceptions.BoxKeyError: "'ConfigBox' object has no attribute 'data_validation'"

During handling of the above exception, another exception occurred:

Traceback (most recent call last):
  File "C:\Users\pr141\PycharmProjects\pythonProject\venv\Lib\site-packages\box\box.py", line 503, in __getitem__
    return super().__getitem__(item)
           ^^^^^^^^^^^^^^^^^^^^^^^^^
KeyError: 'data_validation'

The above exception was the direct cause of the following exception:

Traceback (most recent call last):
  File "C:\Users\pr141\PycharmProjects\pythonProject\venv\Lib\site-packages\box\box.py", line 536, in __getattr__
    value = self.__getitem__(item, _ignore_default=True)
            ^^^^^^^^^^^^^^^^^^^^^^^^^^^^^^^^^^^^^^^^^^^^
  File "C:\Users\pr141\PycharmProjects\pythonProject\venv\Lib\site-packages\box\box.py", line 524, in __getitem__
    raise BoxKeyError(str(err)) from _exception_cause(err)
box.exceptions.BoxKeyError: "'data_validation'"

During handling of the above exception, another exception occurred:

Traceback (most recent call last):
  File "C:\Users\pr141\PycharmProjects\pythonProject\venv\Lib\site-packages\box\box.py", line 538, in __getattr__
    value = object.__getattribute__(self, item)
            ^^^^^^^^^^^^^^^^^^^^^^^^^^^^^^^^^^^
AttributeError: 'ConfigBox' object has no attribute 'data_validation'

The above exception was the direct cause of the following exception:

Traceback (most recent call last):
  File "D:\Projects\Stock_Market_Predictor_ETE\main.py", line 23, in <module>
    obj.main()
  File "D:\Projects\Stock_Market_Predictor_ETE\src\stock_predictor\pipeline\stage_02_data_validation.py", line 15, in main
    data_ingestion_config = config.get_data_validation_config()
                            ^^^^^^^^^^^^^^^^^^^^^^^^^^^^^^^^^^^
  File "D:\Projects\Stock_Market_Predictor_ETE\src\stock_predictor\config\configuration.py", line 35, in get_data_validation_config
    config = self.config.data_validation
             ^^^^^^^^^^^^^^^^^^^^^^^^^^^
  File "C:\Users\pr141\PycharmProjects\pythonProject\venv\Lib\site-packages\box\config_box.py", line 30, in __getattr__
    return super().__getattr__(item.lower())
           ^^^^^^^^^^^^^^^^^^^^^^^^^^^^^^^^^
  File "C:\Users\pr141\PycharmProjects\pythonProject\venv\Lib\site-packages\box\box.py", line 552, in __getattr__
    raise BoxKeyError(str(err)) from _exception_cause(err)
box.exceptions.BoxKeyError: "'ConfigBox' object has no attribute 'data_validation'"
[2024-05-17 20:22:14,524: INFO: main: >>>>>> stage Data Ingestion stage started <<<<<<]
[2024-05-17 20:22:14,525: INFO: common: yaml file: config\config.yaml loaded successfully]
[2024-05-17 20:22:14,526: INFO: common: yaml file: params.yaml loaded successfully]
[2024-05-17 20:22:14,527: INFO: common: yaml file: schema.yaml loaded successfully]
[2024-05-17 20:22:14,527: INFO: common: created directory at: artifacts]
[2024-05-17 20:22:14,527: INFO: common: created directory at: artifacts/data_ingestion]
[2024-05-17 20:22:14,528: INFO: data_ingestion: file already exists of size: ~ 294 KB]
[2024-05-17 20:22:14,535: INFO: main: >>>>>> stage Data Ingestion stage completed <<<<<<

x==========x]
[2024-05-17 20:22:14,535: INFO: main: >>>>>> stage Data Validation stage started <<<<<<]
[2024-05-17 20:22:14,536: INFO: common: yaml file: config\config.yaml loaded successfully]
[2024-05-17 20:22:14,536: INFO: common: yaml file: params.yaml loaded successfully]
[2024-05-17 20:22:14,537: INFO: common: yaml file: schema.yaml loaded successfully]
[2024-05-17 20:22:14,537: INFO: common: created directory at: artifacts]
[2024-05-17 20:22:14,538: INFO: common: created directory at: artifacts/data_validation]
[2024-05-17 20:22:14,539: ERROR: main: [Errno 2] No such file or directory: 'artifacts/data_ingestion/winequality-red.csv']
Traceback (most recent call last):
  File "D:\Projects\Stock_Market_Predictor_ETE\main.py", line 23, in <module>
    obj.main()
  File "D:\Projects\Stock_Market_Predictor_ETE\src\stock_predictor\pipeline\stage_02_data_validation.py", line 17, in main
    data_ingestion.validate_all_columns()
  File "D:\Projects\Stock_Market_Predictor_ETE\src\stock_predictor\components\data_validation.py", line 33, in validate_all_columns
    raise e
  File "D:\Projects\Stock_Market_Predictor_ETE\src\stock_predictor\components\data_validation.py", line 15, in validate_all_columns
    data = pd.read_csv(self.config.unzip_data_dir)
           ^^^^^^^^^^^^^^^^^^^^^^^^^^^^^^^^^^^^^^^
  File "C:\Users\pr141\AppData\Local\Programs\Python\Python312\Lib\site-packages\pandas\io\parsers\readers.py", line 1026, in read_csv
    return _read(filepath_or_buffer, kwds)
           ^^^^^^^^^^^^^^^^^^^^^^^^^^^^^^^
  File "C:\Users\pr141\AppData\Local\Programs\Python\Python312\Lib\site-packages\pandas\io\parsers\readers.py", line 620, in _read
    parser = TextFileReader(filepath_or_buffer, **kwds)
             ^^^^^^^^^^^^^^^^^^^^^^^^^^^^^^^^^^^^^^^^^^
  File "C:\Users\pr141\AppData\Local\Programs\Python\Python312\Lib\site-packages\pandas\io\parsers\readers.py", line 1620, in __init__
    self._engine = self._make_engine(f, self.engine)
                   ^^^^^^^^^^^^^^^^^^^^^^^^^^^^^^^^^
  File "C:\Users\pr141\AppData\Local\Programs\Python\Python312\Lib\site-packages\pandas\io\parsers\readers.py", line 1880, in _make_engine
    self.handles = get_handle(
                   ^^^^^^^^^^^
  File "C:\Users\pr141\AppData\Local\Programs\Python\Python312\Lib\site-packages\pandas\io\common.py", line 873, in get_handle
    handle = open(
             ^^^^^
FileNotFoundError: [Errno 2] No such file or directory: 'artifacts/data_ingestion/winequality-red.csv'
[2024-05-17 20:22:36,113: INFO: main: >>>>>> stage Data Ingestion stage started <<<<<<]
[2024-05-17 20:22:36,114: INFO: common: yaml file: config\config.yaml loaded successfully]
[2024-05-17 20:22:36,115: INFO: common: yaml file: params.yaml loaded successfully]
[2024-05-17 20:22:36,115: INFO: common: yaml file: schema.yaml loaded successfully]
[2024-05-17 20:22:36,116: INFO: common: created directory at: artifacts]
[2024-05-17 20:22:36,116: INFO: common: created directory at: artifacts/data_ingestion]
[2024-05-17 20:22:36,116: INFO: data_ingestion: file already exists of size: ~ 294 KB]
[2024-05-17 20:22:36,122: INFO: main: >>>>>> stage Data Ingestion stage completed <<<<<<

x==========x]
[2024-05-17 20:22:36,123: INFO: main: >>>>>> stage Data Validation stage started <<<<<<]
[2024-05-17 20:22:36,124: INFO: common: yaml file: config\config.yaml loaded successfully]
[2024-05-17 20:22:36,124: INFO: common: yaml file: params.yaml loaded successfully]
[2024-05-17 20:22:36,125: INFO: common: yaml file: schema.yaml loaded successfully]
[2024-05-17 20:22:36,125: INFO: common: created directory at: artifacts]
[2024-05-17 20:22:36,126: INFO: common: created directory at: artifacts/data_validation]
[2024-05-17 20:22:36,127: ERROR: main: [Errno 2] No such file or directory: 'artifacts/data_ingestion/winequality-red.csv']
Traceback (most recent call last):
  File "D:\Projects\Stock_Market_Predictor_ETE\main.py", line 23, in <module>
    obj.main()
  File "D:\Projects\Stock_Market_Predictor_ETE\src\stock_predictor\pipeline\stage_02_data_validation.py", line 17, in main
    data_ingestion.validate_all_columns()
  File "D:\Projects\Stock_Market_Predictor_ETE\src\stock_predictor\components\data_validation.py", line 33, in validate_all_columns
    raise e
  File "D:\Projects\Stock_Market_Predictor_ETE\src\stock_predictor\components\data_validation.py", line 15, in validate_all_columns
    data = pd.read_csv(self.config.unzip_data_dir)
           ^^^^^^^^^^^^^^^^^^^^^^^^^^^^^^^^^^^^^^^
  File "C:\Users\pr141\AppData\Local\Programs\Python\Python312\Lib\site-packages\pandas\io\parsers\readers.py", line 1026, in read_csv
    return _read(filepath_or_buffer, kwds)
           ^^^^^^^^^^^^^^^^^^^^^^^^^^^^^^^
  File "C:\Users\pr141\AppData\Local\Programs\Python\Python312\Lib\site-packages\pandas\io\parsers\readers.py", line 620, in _read
    parser = TextFileReader(filepath_or_buffer, **kwds)
             ^^^^^^^^^^^^^^^^^^^^^^^^^^^^^^^^^^^^^^^^^^
  File "C:\Users\pr141\AppData\Local\Programs\Python\Python312\Lib\site-packages\pandas\io\parsers\readers.py", line 1620, in __init__
    self._engine = self._make_engine(f, self.engine)
                   ^^^^^^^^^^^^^^^^^^^^^^^^^^^^^^^^^
  File "C:\Users\pr141\AppData\Local\Programs\Python\Python312\Lib\site-packages\pandas\io\parsers\readers.py", line 1880, in _make_engine
    self.handles = get_handle(
                   ^^^^^^^^^^^
  File "C:\Users\pr141\AppData\Local\Programs\Python\Python312\Lib\site-packages\pandas\io\common.py", line 873, in get_handle
    handle = open(
             ^^^^^
FileNotFoundError: [Errno 2] No such file or directory: 'artifacts/data_ingestion/winequality-red.csv'
[2024-05-17 20:22:46,453: INFO: main: >>>>>> stage Data Ingestion stage started <<<<<<]
[2024-05-17 20:22:46,455: INFO: common: yaml file: config\config.yaml loaded successfully]
[2024-05-17 20:22:46,456: INFO: common: yaml file: params.yaml loaded successfully]
[2024-05-17 20:22:46,456: INFO: common: yaml file: schema.yaml loaded successfully]
[2024-05-17 20:22:46,457: INFO: common: created directory at: artifacts]
[2024-05-17 20:22:46,458: INFO: common: created directory at: artifacts/data_ingestion]
[2024-05-17 20:22:46,458: INFO: data_ingestion: file already exists of size: ~ 294 KB]
[2024-05-17 20:22:46,465: INFO: main: >>>>>> stage Data Ingestion stage completed <<<<<<

x==========x]
[2024-05-17 20:22:46,465: INFO: main: >>>>>> stage Data Validation stage started <<<<<<]
[2024-05-17 20:22:46,466: INFO: common: yaml file: config\config.yaml loaded successfully]
[2024-05-17 20:22:46,467: INFO: common: yaml file: params.yaml loaded successfully]
[2024-05-17 20:22:46,468: INFO: common: yaml file: schema.yaml loaded successfully]
[2024-05-17 20:22:46,468: INFO: common: created directory at: artifacts]
[2024-05-17 20:22:46,469: INFO: common: created directory at: artifacts/data_validation]
[2024-05-17 20:22:46,499: INFO: main: >>>>>> stage Data Validation stage completed <<<<<<

x==========x]
[2024-05-18 12:06:49,405: INFO: common: yaml file: config\config.yaml loaded successfully]
[2024-05-18 12:06:49,420: INFO: common: yaml file: params.yaml loaded successfully]
[2024-05-18 12:06:49,425: INFO: common: yaml file: schema.yaml loaded successfully]
[2024-05-18 12:06:49,426: INFO: common: created directory at: artifacts]
[2024-05-18 12:06:49,427: INFO: common: created directory at: artifacts/data_transformation]
[2024-05-18 12:08:36,755: INFO: common: yaml file: config\config.yaml loaded successfully]
[2024-05-18 12:08:36,757: INFO: common: yaml file: params.yaml loaded successfully]
[2024-05-18 12:08:36,758: INFO: common: yaml file: schema.yaml loaded successfully]
[2024-05-18 12:08:36,759: INFO: common: created directory at: artifacts]
[2024-05-18 12:08:36,759: INFO: common: created directory at: artifacts/data_transformation]
[2024-05-19 16:33:31,712: INFO: common: yaml file: config\config.yaml loaded successfully]
[2024-05-19 16:33:31,777: INFO: common: yaml file: params.yaml loaded successfully]
[2024-05-19 16:33:31,787: INFO: common: yaml file: schema.yaml loaded successfully]
[2024-05-19 16:33:31,790: INFO: common: created directory at: artifacts]
[2024-05-19 16:33:31,791: INFO: common: created directory at: artifacts/data_transformation]
[2024-05-19 16:34:29,520: INFO: common: yaml file: config\config.yaml loaded successfully]
[2024-05-19 16:34:29,521: INFO: common: yaml file: params.yaml loaded successfully]
[2024-05-19 16:34:29,523: INFO: common: yaml file: schema.yaml loaded successfully]
[2024-05-19 16:34:29,524: INFO: common: created directory at: artifacts]
[2024-05-19 16:34:29,525: INFO: common: created directory at: artifacts/data_transformation]
[2024-05-19 16:44:25,434: INFO: common: yaml file: config\config.yaml loaded successfully]
[2024-05-19 16:44:25,436: INFO: common: yaml file: params.yaml loaded successfully]
[2024-05-19 16:44:25,437: INFO: common: yaml file: schema.yaml loaded successfully]
[2024-05-19 16:44:25,438: INFO: common: created directory at: artifacts]
[2024-05-19 16:44:25,439: INFO: common: created directory at: artifacts/data_transformation]
[2024-05-19 16:44:53,577: INFO: common: yaml file: config\config.yaml loaded successfully]
[2024-05-19 16:44:53,578: INFO: common: yaml file: params.yaml loaded successfully]
[2024-05-19 16:44:53,580: INFO: common: yaml file: schema.yaml loaded successfully]
[2024-05-19 16:44:53,581: INFO: common: created directory at: artifacts]
[2024-05-19 16:44:53,581: INFO: common: created directory at: artifacts/data_transformation]
[2024-05-19 16:45:22,269: INFO: common: yaml file: config\config.yaml loaded successfully]
[2024-05-19 16:45:22,270: INFO: common: yaml file: params.yaml loaded successfully]
[2024-05-19 16:45:22,271: INFO: common: yaml file: schema.yaml loaded successfully]
[2024-05-19 16:45:22,272: INFO: common: created directory at: artifacts]
[2024-05-19 16:45:22,273: INFO: common: created directory at: artifacts/data_transformation]
[2024-05-19 16:45:35,647: INFO: common: yaml file: config\config.yaml loaded successfully]
[2024-05-19 16:45:35,649: INFO: common: yaml file: params.yaml loaded successfully]
[2024-05-19 16:45:35,650: INFO: common: yaml file: schema.yaml loaded successfully]
[2024-05-19 16:45:35,650: INFO: common: created directory at: artifacts]
[2024-05-19 16:45:35,651: INFO: common: created directory at: artifacts/data_transformation]
[2024-05-20 19:47:39,493: INFO: main: >>>>>> stage Data Ingestion stage started <<<<<<]
[2024-05-20 19:47:39,504: INFO: common: yaml file: config\config.yaml loaded successfully]
[2024-05-20 19:47:39,508: INFO: common: yaml file: params.yaml loaded successfully]
[2024-05-20 19:47:39,514: INFO: common: yaml file: schema.yaml loaded successfully]
[2024-05-20 19:47:39,515: INFO: common: created directory at: artifacts]
[2024-05-20 19:47:39,516: INFO: common: created directory at: artifacts/data_ingestion]
[2024-05-20 19:47:39,516: INFO: data_ingestion: file already exists of size: ~ 294 KB]
[2024-05-20 19:47:39,538: INFO: main: >>>>>> stage Data Ingestion stage completed <<<<<<

x==========x]
[2024-05-20 19:47:39,538: INFO: main: >>>>>> stage Data Validation stage started <<<<<<]
[2024-05-20 19:47:39,540: INFO: common: yaml file: config\config.yaml loaded successfully]
[2024-05-20 19:47:39,540: INFO: common: yaml file: params.yaml loaded successfully]
[2024-05-20 19:47:39,541: INFO: common: yaml file: schema.yaml loaded successfully]
[2024-05-20 19:47:39,542: INFO: common: created directory at: artifacts]
[2024-05-20 19:47:39,542: INFO: common: created directory at: artifacts/data_validation]
[2024-05-20 19:47:39,571: INFO: main: >>>>>> stage Data Validation stage completed <<<<<<

x==========x]
[2024-05-20 20:30:54,657: INFO: common: yaml file: config\config.yaml loaded successfully]
[2024-05-20 20:30:54,665: INFO: common: yaml file: params.yaml loaded successfully]
[2024-05-20 20:30:54,674: INFO: common: yaml file: schema.yaml loaded successfully]
[2024-05-20 20:30:54,675: INFO: common: created directory at: artifacts]
[2024-05-20 20:30:54,676: INFO: common: created directory at: artifacts/data_transformation]
[2024-05-20 20:53:12,150: INFO: common: yaml file: config\config.yaml loaded successfully]
[2024-05-20 20:53:12,156: INFO: common: yaml file: params.yaml loaded successfully]
[2024-05-20 20:53:12,165: INFO: common: yaml file: schema.yaml loaded successfully]
[2024-05-20 20:53:12,166: INFO: common: created directory at: artifacts]
[2024-05-20 20:53:12,167: INFO: common: created directory at: artifacts/data_transformation]
[2024-05-20 20:55:06,505: INFO: main: >>>>>> stage Data Ingestion stage started <<<<<<]
[2024-05-20 20:55:06,508: INFO: common: yaml file: config\config.yaml loaded successfully]
[2024-05-20 20:55:06,508: INFO: common: yaml file: params.yaml loaded successfully]
[2024-05-20 20:55:06,508: INFO: common: yaml file: schema.yaml loaded successfully]
[2024-05-20 20:55:06,509: INFO: common: created directory at: artifacts]
[2024-05-20 20:55:06,510: INFO: common: created directory at: artifacts/data_ingestion]
[2024-05-20 20:55:07,854: INFO: data_ingestion: artifacts/data_ingestion/data.zip download! with following info: 
Connection: close
Content-Length: 300940
Cache-Control: max-age=300
Content-Security-Policy: default-src 'none'; style-src 'unsafe-inline'; sandbox
Content-Type: application/zip
ETag: "d076672f1746d4eb167a00b3b2c7f6458cc7ecfa4fa23f72f3f26faa16aaae43"
Strict-Transport-Security: max-age=31536000
X-Content-Type-Options: nosniff
X-Frame-Options: deny
X-XSS-Protection: 1; mode=block
X-GitHub-Request-Id: B706:8A8A2:2F3BC7:405801:664B6B51
Accept-Ranges: bytes
Date: Mon, 20 May 2024 15:25:07 GMT
Via: 1.1 varnish
X-Served-By: cache-maa10221-MAA
X-Cache: MISS
X-Cache-Hits: 0
X-Timer: S1716218707.237791,VS0,VE319
Vary: Authorization,Accept-Encoding,Origin
Access-Control-Allow-Origin: *
Cross-Origin-Resource-Policy: cross-origin
X-Fastly-Request-ID: 332560f5ef3c82f6a97bd002b0afb6fcb165ce1c
Expires: Mon, 20 May 2024 15:30:07 GMT
Source-Age: 0

]
[2024-05-20 20:55:07,868: INFO: main: >>>>>> stage Data Ingestion stage completed <<<<<<

x==========x]
[2024-05-20 20:55:07,868: INFO: main: >>>>>> stage Data Validation stage started <<<<<<]
[2024-05-20 20:55:07,869: INFO: common: yaml file: config\config.yaml loaded successfully]
[2024-05-20 20:55:07,870: INFO: common: yaml file: params.yaml loaded successfully]
[2024-05-20 20:55:07,871: INFO: common: yaml file: schema.yaml loaded successfully]
[2024-05-20 20:55:07,871: INFO: common: created directory at: artifacts]
[2024-05-20 20:55:07,871: INFO: common: created directory at: artifacts/data_validation]
[2024-05-20 20:55:07,895: INFO: main: >>>>>> stage Data Validation stage completed <<<<<<

x==========x]
[2024-05-20 20:56:02,696: INFO: main: >>>>>> stage Data Ingestion stage started <<<<<<]
[2024-05-20 20:56:02,697: INFO: common: yaml file: config\config.yaml loaded successfully]
[2024-05-20 20:56:02,698: INFO: common: yaml file: params.yaml loaded successfully]
[2024-05-20 20:56:02,699: INFO: common: yaml file: schema.yaml loaded successfully]
[2024-05-20 20:56:02,699: INFO: common: created directory at: artifacts]
[2024-05-20 20:56:02,700: INFO: common: created directory at: artifacts/data_ingestion]
[2024-05-20 20:56:03,579: INFO: data_ingestion: artifacts/data_ingestion/data.zip download! with following info: 
Connection: close
Content-Length: 300940
Cache-Control: max-age=300
Content-Security-Policy: default-src 'none'; style-src 'unsafe-inline'; sandbox
Content-Type: application/zip
ETag: "d076672f1746d4eb167a00b3b2c7f6458cc7ecfa4fa23f72f3f26faa16aaae43"
Strict-Transport-Security: max-age=31536000
X-Content-Type-Options: nosniff
X-Frame-Options: deny
X-XSS-Protection: 1; mode=block
X-GitHub-Request-Id: B706:8A8A2:2F3BC7:405801:664B6B51
Accept-Ranges: bytes
Date: Mon, 20 May 2024 15:26:03 GMT
Via: 1.1 varnish
X-Served-By: cache-maa10230-MAA
X-Cache: HIT
X-Cache-Hits: 1
X-Timer: S1716218763.226865,VS0,VE1
Vary: Authorization,Accept-Encoding,Origin
Access-Control-Allow-Origin: *
Cross-Origin-Resource-Policy: cross-origin
X-Fastly-Request-ID: 099debc7faf7a8e8cb43791d74914ab44e76d57c
Expires: Mon, 20 May 2024 15:31:03 GMT
Source-Age: 56

]
[2024-05-20 20:56:03,596: INFO: main: >>>>>> stage Data Ingestion stage completed <<<<<<

x==========x]
[2024-05-20 20:56:03,596: INFO: main: >>>>>> stage Data Validation stage started <<<<<<]
[2024-05-20 20:56:03,597: INFO: common: yaml file: config\config.yaml loaded successfully]
[2024-05-20 20:56:03,598: INFO: common: yaml file: params.yaml loaded successfully]
[2024-05-20 20:56:03,599: INFO: common: yaml file: schema.yaml loaded successfully]
[2024-05-20 20:56:03,600: INFO: common: created directory at: artifacts]
[2024-05-20 20:56:03,600: INFO: common: created directory at: artifacts/data_validation]
[2024-05-20 20:56:03,623: INFO: main: >>>>>> stage Data Validation stage completed <<<<<<

x==========x]
[2024-05-20 20:56:03,623: INFO: main: >>>>>> stage Data Transformation stage started <<<<<<]
[2024-05-20 20:56:03,626: INFO: common: yaml file: config\config.yaml loaded successfully]
[2024-05-20 20:56:03,626: INFO: common: yaml file: params.yaml loaded successfully]
[2024-05-20 20:56:03,627: INFO: common: yaml file: schema.yaml loaded successfully]
[2024-05-20 20:56:03,628: INFO: common: created directory at: artifacts]
[2024-05-20 20:56:03,628: INFO: common: created directory at: artifacts/data_transformation]
[2024-05-20 20:56:03,825: INFO: data_transformation: Splitted data into training and test sets]
[2024-05-20 20:56:03,826: INFO: data_transformation: (12225, 8)]
[2024-05-20 20:56:03,826: INFO: data_transformation: (4075, 8)]
[2024-05-20 20:56:03,827: INFO: main: >>>>>> stage Data Transformation stage completed <<<<<<

x==========x]
[2024-05-20 21:45:09,232: INFO: main: >>>>>> stage Data Ingestion stage started <<<<<<]
[2024-05-20 21:45:09,235: INFO: common: yaml file: config\config.yaml loaded successfully]
[2024-05-20 21:45:09,235: INFO: common: yaml file: params.yaml loaded successfully]
[2024-05-20 21:45:09,236: INFO: common: yaml file: schema.yaml loaded successfully]
[2024-05-20 21:45:09,237: INFO: common: created directory at: artifacts]
[2024-05-20 21:45:09,237: INFO: common: created directory at: artifacts/data_ingestion]
[2024-05-20 21:45:10,342: INFO: data_ingestion: artifacts/data_ingestion/data.zip download! with following info: 
Connection: close
Content-Length: 300940
Cache-Control: max-age=300
Content-Security-Policy: default-src 'none'; style-src 'unsafe-inline'; sandbox
Content-Type: application/zip
ETag: "d076672f1746d4eb167a00b3b2c7f6458cc7ecfa4fa23f72f3f26faa16aaae43"
Strict-Transport-Security: max-age=31536000
X-Content-Type-Options: nosniff
X-Frame-Options: deny
X-XSS-Protection: 1; mode=block
X-GitHub-Request-Id: B706:8A8A2:2F3BC7:405801:664B6B51
Accept-Ranges: bytes
Date: Mon, 20 May 2024 16:15:10 GMT
Via: 1.1 varnish
X-Served-By: cache-maa10238-MAA
X-Cache: HIT
X-Cache-Hits: 0
X-Timer: S1716221710.898244,VS0,VE297
Vary: Authorization,Accept-Encoding,Origin
Access-Control-Allow-Origin: *
Cross-Origin-Resource-Policy: cross-origin
X-Fastly-Request-ID: 5e534ea857fdc6629e076ac237a7d2aa4fcfa65f
Expires: Mon, 20 May 2024 16:20:10 GMT
Source-Age: 0

]
[2024-05-20 21:45:10,359: INFO: main: >>>>>> stage Data Ingestion stage completed <<<<<<

x==========x]
[2024-05-20 21:45:10,359: INFO: main: >>>>>> stage Data Validation stage started <<<<<<]
[2024-05-20 21:45:10,360: INFO: common: yaml file: config\config.yaml loaded successfully]
[2024-05-20 21:45:10,361: INFO: common: yaml file: params.yaml loaded successfully]
[2024-05-20 21:45:10,361: INFO: common: yaml file: schema.yaml loaded successfully]
[2024-05-20 21:45:10,362: INFO: common: created directory at: artifacts]
[2024-05-20 21:45:10,362: INFO: common: created directory at: artifacts/data_validation]
[2024-05-20 21:45:10,384: INFO: main: >>>>>> stage Data Validation stage completed <<<<<<

x==========x]
[2024-05-20 21:45:10,384: INFO: main: >>>>>> stage Data Transformation stage started <<<<<<]
[2024-05-20 21:45:10,386: INFO: common: yaml file: config\config.yaml loaded successfully]
[2024-05-20 21:45:10,388: INFO: common: yaml file: params.yaml loaded successfully]
[2024-05-20 21:45:10,388: INFO: common: yaml file: schema.yaml loaded successfully]
[2024-05-20 21:45:10,389: INFO: common: created directory at: artifacts]
[2024-05-20 21:45:10,389: INFO: common: created directory at: artifacts/data_transformation]
[2024-05-20 21:45:10,578: INFO: data_transformation: Splitted data into training and test sets]
[2024-05-20 21:45:10,578: INFO: data_transformation: (12225, 8)]
[2024-05-20 21:45:10,579: INFO: data_transformation: (4075, 8)]
[2024-05-20 21:45:10,579: INFO: main: >>>>>> stage Data Transformation stage completed <<<<<<

x==========x]
[2024-05-20 21:45:10,580: INFO: main: >>>>>> stage Model Trainer stage started <<<<<<]
[2024-05-20 21:45:10,581: INFO: common: yaml file: config\config.yaml loaded successfully]
[2024-05-20 21:45:10,582: INFO: common: yaml file: params.yaml loaded successfully]
[2024-05-20 21:45:10,582: INFO: common: yaml file: schema.yaml loaded successfully]
[2024-05-20 21:45:10,583: INFO: common: created directory at: artifacts]
[2024-05-20 21:45:10,584: INFO: common: created directory at: artifacts/model_trainer]
[2024-05-20 21:45:10,584: ERROR: main: 'str' object has no attribute 'max_depth']
Traceback (most recent call last):
  File "D:\Projects\Stock_Market_Predictor_ETE\main.py", line 47, in <module>
    obj.main()
  File "D:\Projects\Stock_Market_Predictor_ETE\src\stock_predictor\pipeline\stage_04_model_trainer.py", line 15, in main
    model_training_config = config.get_model_trainer_config()
                            ^^^^^^^^^^^^^^^^^^^^^^^^^^^^^^^^^
  File "D:\Projects\Stock_Market_Predictor_ETE\src\stock_predictor\config\configuration.py", line 70, in get_model_trainer_config
    max_depth=params.max_depth,
              ^^^^^^^^^^^^^^^^
AttributeError: 'str' object has no attribute 'max_depth'
[2024-05-21 10:11:59,985: INFO: main: >>>>>> stage Data Ingestion stage started <<<<<<]
[2024-05-21 10:11:59,987: INFO: common: yaml file: config\config.yaml loaded successfully]
[2024-05-21 10:11:59,987: INFO: common: yaml file: params.yaml loaded successfully]
[2024-05-21 10:11:59,988: INFO: common: yaml file: schema.yaml loaded successfully]
[2024-05-21 10:11:59,989: INFO: common: created directory at: artifacts]
[2024-05-21 10:11:59,989: INFO: common: created directory at: artifacts/data_ingestion]
[2024-05-21 10:11:59,989: INFO: data_ingestion: file already exists of size: ~ 294 KB]
[2024-05-21 10:11:59,996: INFO: main: >>>>>> stage Data Ingestion stage completed <<<<<<

x==========x]
[2024-05-21 10:11:59,996: INFO: main: >>>>>> stage Data Validation stage started <<<<<<]
[2024-05-21 10:11:59,998: INFO: common: yaml file: config\config.yaml loaded successfully]
[2024-05-21 10:11:59,998: INFO: common: yaml file: params.yaml loaded successfully]
[2024-05-21 10:11:59,999: INFO: common: yaml file: schema.yaml loaded successfully]
[2024-05-21 10:11:59,999: INFO: common: created directory at: artifacts]
[2024-05-21 10:11:59,999: INFO: common: created directory at: artifacts/data_validation]
[2024-05-21 10:12:00,023: INFO: main: >>>>>> stage Data Validation stage completed <<<<<<

x==========x]
[2024-05-21 10:12:00,023: INFO: main: >>>>>> stage Data Transformation stage started <<<<<<]
[2024-05-21 10:12:00,024: INFO: common: yaml file: config\config.yaml loaded successfully]
[2024-05-21 10:12:00,025: INFO: common: yaml file: params.yaml loaded successfully]
[2024-05-21 10:12:00,026: INFO: common: yaml file: schema.yaml loaded successfully]
[2024-05-21 10:12:00,026: INFO: common: created directory at: artifacts]
[2024-05-21 10:12:00,027: INFO: common: created directory at: artifacts/data_transformation]
[2024-05-21 10:12:00,219: INFO: data_transformation: Splitted data into training and test sets]
[2024-05-21 10:12:00,220: INFO: data_transformation: (12225, 8)]
[2024-05-21 10:12:00,220: INFO: data_transformation: (4075, 8)]
[2024-05-21 10:12:00,221: INFO: main: >>>>>> stage Data Transformation stage completed <<<<<<

x==========x]
[2024-05-21 10:12:00,221: INFO: main: >>>>>> stage Model Trainer stage started <<<<<<]
[2024-05-21 10:12:00,222: INFO: common: yaml file: config\config.yaml loaded successfully]
[2024-05-21 10:12:00,223: INFO: common: yaml file: params.yaml loaded successfully]
[2024-05-21 10:12:00,224: INFO: common: yaml file: schema.yaml loaded successfully]
[2024-05-21 10:12:00,225: INFO: common: created directory at: artifacts]
[2024-05-21 10:12:00,225: INFO: common: created directory at: artifacts/model_trainer]
[2024-05-21 10:12:00,225: ERROR: main: 'str' object has no attribute 'max_depth']
Traceback (most recent call last):
  File "D:\Projects\Stock_Market_Predictor_ETE\main.py", line 47, in <module>
    obj.main()
  File "D:\Projects\Stock_Market_Predictor_ETE\src\stock_predictor\pipeline\stage_04_model_trainer.py", line 15, in main
    model_training_config = config.get_model_trainer_config()
                            ^^^^^^^^^^^^^^^^^^^^^^^^^^^^^^^^^
  File "D:\Projects\Stock_Market_Predictor_ETE\src\stock_predictor\config\configuration.py", line 70, in get_model_trainer_config
    max_depth=params.max_depth,
              ^^^^^^^^^^^^^^^^
AttributeError: 'str' object has no attribute 'max_depth'
[2024-05-21 10:13:43,723: INFO: main: >>>>>> stage Data Ingestion stage started <<<<<<]
[2024-05-21 10:13:43,725: INFO: common: yaml file: config\config.yaml loaded successfully]
[2024-05-21 10:13:43,725: INFO: common: yaml file: params.yaml loaded successfully]
[2024-05-21 10:13:43,726: INFO: common: yaml file: schema.yaml loaded successfully]
[2024-05-21 10:13:43,727: INFO: common: created directory at: artifacts]
[2024-05-21 10:13:43,727: INFO: common: created directory at: artifacts/data_ingestion]
[2024-05-21 10:13:43,728: INFO: data_ingestion: file already exists of size: ~ 294 KB]
[2024-05-21 10:13:43,734: INFO: main: >>>>>> stage Data Ingestion stage completed <<<<<<

x==========x]
[2024-05-21 10:13:43,735: INFO: main: >>>>>> stage Data Validation stage started <<<<<<]
[2024-05-21 10:13:43,736: INFO: common: yaml file: config\config.yaml loaded successfully]
[2024-05-21 10:13:43,736: INFO: common: yaml file: params.yaml loaded successfully]
[2024-05-21 10:13:43,737: INFO: common: yaml file: schema.yaml loaded successfully]
[2024-05-21 10:13:43,738: INFO: common: created directory at: artifacts]
[2024-05-21 10:13:43,738: INFO: common: created directory at: artifacts/data_validation]
[2024-05-21 10:13:43,757: INFO: main: >>>>>> stage Data Validation stage completed <<<<<<

x==========x]
[2024-05-21 10:13:43,758: INFO: main: >>>>>> stage Data Transformation stage started <<<<<<]
[2024-05-21 10:13:43,759: INFO: common: yaml file: config\config.yaml loaded successfully]
[2024-05-21 10:13:43,760: INFO: common: yaml file: params.yaml loaded successfully]
[2024-05-21 10:13:43,760: INFO: common: yaml file: schema.yaml loaded successfully]
[2024-05-21 10:13:43,761: INFO: common: created directory at: artifacts]
[2024-05-21 10:13:43,761: INFO: common: created directory at: artifacts/data_transformation]
[2024-05-21 10:13:43,944: INFO: data_transformation: Splitted data into training and test sets]
[2024-05-21 10:13:43,944: INFO: data_transformation: (12225, 8)]
[2024-05-21 10:13:43,945: INFO: data_transformation: (4075, 8)]
[2024-05-21 10:13:43,945: INFO: main: >>>>>> stage Data Transformation stage completed <<<<<<

x==========x]
[2024-05-21 10:13:43,946: INFO: main: >>>>>> stage Model Trainer stage started <<<<<<]
[2024-05-21 10:13:43,948: INFO: common: yaml file: config\config.yaml loaded successfully]
[2024-05-21 10:13:43,948: INFO: common: yaml file: params.yaml loaded successfully]
[2024-05-21 10:13:43,949: INFO: common: yaml file: schema.yaml loaded successfully]
[2024-05-21 10:13:43,950: INFO: common: created directory at: artifacts]
[2024-05-21 10:13:43,950: INFO: common: created directory at: artifacts/model_trainer]
[2024-05-21 10:13:43,951: ERROR: main: "'ConfigBox' object has no attribute 'name'"]
Traceback (most recent call last):
  File "D:\Projects\Stock_Market_Predictor_ETE\env\Lib\site-packages\box\box.py", line 503, in __getitem__
    return super().__getitem__(item)
           ^^^^^^^^^^^^^^^^^^^^^^^^^
KeyError: 'name'

The above exception was the direct cause of the following exception:

Traceback (most recent call last):
  File "D:\Projects\Stock_Market_Predictor_ETE\env\Lib\site-packages\box\box.py", line 536, in __getattr__
    value = self.__getitem__(item, _ignore_default=True)
            ^^^^^^^^^^^^^^^^^^^^^^^^^^^^^^^^^^^^^^^^^^^^
  File "D:\Projects\Stock_Market_Predictor_ETE\env\Lib\site-packages\box\box.py", line 524, in __getitem__
    raise BoxKeyError(str(err)) from _exception_cause(err)
box.exceptions.BoxKeyError: "'name'"

During handling of the above exception, another exception occurred:

Traceback (most recent call last):
  File "D:\Projects\Stock_Market_Predictor_ETE\env\Lib\site-packages\box\box.py", line 538, in __getattr__
    value = object.__getattribute__(self, item)
            ^^^^^^^^^^^^^^^^^^^^^^^^^^^^^^^^^^^
AttributeError: 'ConfigBox' object has no attribute 'name'

The above exception was the direct cause of the following exception:

Traceback (most recent call last):
  File "D:\Projects\Stock_Market_Predictor_ETE\env\Lib\site-packages\box\config_box.py", line 28, in __getattr__
    return super().__getattr__(item)
           ^^^^^^^^^^^^^^^^^^^^^^^^^
  File "D:\Projects\Stock_Market_Predictor_ETE\env\Lib\site-packages\box\box.py", line 552, in __getattr__
    raise BoxKeyError(str(err)) from _exception_cause(err)
box.exceptions.BoxKeyError: "'ConfigBox' object has no attribute 'name'"

During handling of the above exception, another exception occurred:

Traceback (most recent call last):
  File "D:\Projects\Stock_Market_Predictor_ETE\env\Lib\site-packages\box\box.py", line 503, in __getitem__
    return super().__getitem__(item)
           ^^^^^^^^^^^^^^^^^^^^^^^^^
KeyError: 'name'

The above exception was the direct cause of the following exception:

Traceback (most recent call last):
  File "D:\Projects\Stock_Market_Predictor_ETE\env\Lib\site-packages\box\box.py", line 536, in __getattr__
    value = self.__getitem__(item, _ignore_default=True)
            ^^^^^^^^^^^^^^^^^^^^^^^^^^^^^^^^^^^^^^^^^^^^
  File "D:\Projects\Stock_Market_Predictor_ETE\env\Lib\site-packages\box\box.py", line 524, in __getitem__
    raise BoxKeyError(str(err)) from _exception_cause(err)
box.exceptions.BoxKeyError: "'name'"

During handling of the above exception, another exception occurred:

Traceback (most recent call last):
  File "D:\Projects\Stock_Market_Predictor_ETE\env\Lib\site-packages\box\box.py", line 538, in __getattr__
    value = object.__getattribute__(self, item)
            ^^^^^^^^^^^^^^^^^^^^^^^^^^^^^^^^^^^
AttributeError: 'ConfigBox' object has no attribute 'name'

The above exception was the direct cause of the following exception:

Traceback (most recent call last):
  File "D:\Projects\Stock_Market_Predictor_ETE\main.py", line 47, in <module>
    obj.main()
  File "D:\Projects\Stock_Market_Predictor_ETE\src\stock_predictor\pipeline\stage_04_model_trainer.py", line 15, in main
    model_training_config = config.get_model_trainer_config()
                            ^^^^^^^^^^^^^^^^^^^^^^^^^^^^^^^^^
  File "D:\Projects\Stock_Market_Predictor_ETE\src\stock_predictor\config\configuration.py", line 72, in get_model_trainer_config
    target_column=config.name
                  ^^^^^^^^^^^
  File "D:\Projects\Stock_Market_Predictor_ETE\env\Lib\site-packages\box\config_box.py", line 30, in __getattr__
    return super().__getattr__(item.lower())
           ^^^^^^^^^^^^^^^^^^^^^^^^^^^^^^^^^
  File "D:\Projects\Stock_Market_Predictor_ETE\env\Lib\site-packages\box\box.py", line 552, in __getattr__
    raise BoxKeyError(str(err)) from _exception_cause(err)
box.exceptions.BoxKeyError: "'ConfigBox' object has no attribute 'name'"
[2024-05-21 10:14:42,247: INFO: main: >>>>>> stage Data Ingestion stage started <<<<<<]
[2024-05-21 10:14:42,249: INFO: common: yaml file: config\config.yaml loaded successfully]
[2024-05-21 10:14:42,250: INFO: common: yaml file: params.yaml loaded successfully]
[2024-05-21 10:14:42,251: INFO: common: yaml file: schema.yaml loaded successfully]
[2024-05-21 10:14:42,251: INFO: common: created directory at: artifacts]
[2024-05-21 10:14:42,252: INFO: common: created directory at: artifacts/data_ingestion]
[2024-05-21 10:14:42,252: INFO: data_ingestion: file already exists of size: ~ 294 KB]
[2024-05-21 10:14:42,259: INFO: main: >>>>>> stage Data Ingestion stage completed <<<<<<

x==========x]
[2024-05-21 10:14:42,259: INFO: main: >>>>>> stage Data Validation stage started <<<<<<]
[2024-05-21 10:14:42,260: INFO: common: yaml file: config\config.yaml loaded successfully]
[2024-05-21 10:14:42,261: INFO: common: yaml file: params.yaml loaded successfully]
[2024-05-21 10:14:42,261: INFO: common: yaml file: schema.yaml loaded successfully]
[2024-05-21 10:14:42,262: INFO: common: created directory at: artifacts]
[2024-05-21 10:14:42,262: INFO: common: created directory at: artifacts/data_validation]
[2024-05-21 10:14:42,280: INFO: main: >>>>>> stage Data Validation stage completed <<<<<<

x==========x]
[2024-05-21 10:14:42,280: INFO: main: >>>>>> stage Data Transformation stage started <<<<<<]
[2024-05-21 10:14:42,281: INFO: common: yaml file: config\config.yaml loaded successfully]
[2024-05-21 10:14:42,282: INFO: common: yaml file: params.yaml loaded successfully]
[2024-05-21 10:14:42,283: INFO: common: yaml file: schema.yaml loaded successfully]
[2024-05-21 10:14:42,283: INFO: common: created directory at: artifacts]
[2024-05-21 10:14:42,284: INFO: common: created directory at: artifacts/data_transformation]
[2024-05-21 10:14:42,472: INFO: data_transformation: Splitted data into training and test sets]
[2024-05-21 10:14:42,472: INFO: data_transformation: (12225, 8)]
[2024-05-21 10:14:42,472: INFO: data_transformation: (4075, 8)]
[2024-05-21 10:14:42,473: INFO: main: >>>>>> stage Data Transformation stage completed <<<<<<

x==========x]
[2024-05-21 10:14:42,474: INFO: main: >>>>>> stage Model Trainer stage started <<<<<<]
[2024-05-21 10:14:42,475: INFO: common: yaml file: config\config.yaml loaded successfully]
[2024-05-21 10:14:42,476: INFO: common: yaml file: params.yaml loaded successfully]
[2024-05-21 10:14:42,476: INFO: common: yaml file: schema.yaml loaded successfully]
[2024-05-21 10:14:42,477: INFO: common: created directory at: artifacts]
[2024-05-21 10:14:42,477: ERROR: main: "'ConfigBox' object has no attribute 'target_column'"]
Traceback (most recent call last):
  File "D:\Projects\Stock_Market_Predictor_ETE\env\Lib\site-packages\box\box.py", line 503, in __getitem__
    return super().__getitem__(item)
           ^^^^^^^^^^^^^^^^^^^^^^^^^
KeyError: 'TARGET_COLUMN'

The above exception was the direct cause of the following exception:

Traceback (most recent call last):
  File "D:\Projects\Stock_Market_Predictor_ETE\env\Lib\site-packages\box\box.py", line 536, in __getattr__
    value = self.__getitem__(item, _ignore_default=True)
            ^^^^^^^^^^^^^^^^^^^^^^^^^^^^^^^^^^^^^^^^^^^^
  File "D:\Projects\Stock_Market_Predictor_ETE\env\Lib\site-packages\box\box.py", line 524, in __getitem__
    raise BoxKeyError(str(err)) from _exception_cause(err)
box.exceptions.BoxKeyError: "'TARGET_COLUMN'"

During handling of the above exception, another exception occurred:

Traceback (most recent call last):
  File "D:\Projects\Stock_Market_Predictor_ETE\env\Lib\site-packages\box\box.py", line 538, in __getattr__
    value = object.__getattribute__(self, item)
            ^^^^^^^^^^^^^^^^^^^^^^^^^^^^^^^^^^^
AttributeError: 'ConfigBox' object has no attribute 'TARGET_COLUMN'

The above exception was the direct cause of the following exception:

Traceback (most recent call last):
  File "D:\Projects\Stock_Market_Predictor_ETE\env\Lib\site-packages\box\config_box.py", line 28, in __getattr__
    return super().__getattr__(item)
           ^^^^^^^^^^^^^^^^^^^^^^^^^
  File "D:\Projects\Stock_Market_Predictor_ETE\env\Lib\site-packages\box\box.py", line 552, in __getattr__
    raise BoxKeyError(str(err)) from _exception_cause(err)
box.exceptions.BoxKeyError: "'ConfigBox' object has no attribute 'TARGET_COLUMN'"

During handling of the above exception, another exception occurred:

Traceback (most recent call last):
  File "D:\Projects\Stock_Market_Predictor_ETE\env\Lib\site-packages\box\box.py", line 503, in __getitem__
    return super().__getitem__(item)
           ^^^^^^^^^^^^^^^^^^^^^^^^^
KeyError: 'target_column'

The above exception was the direct cause of the following exception:

Traceback (most recent call last):
  File "D:\Projects\Stock_Market_Predictor_ETE\env\Lib\site-packages\box\box.py", line 536, in __getattr__
    value = self.__getitem__(item, _ignore_default=True)
            ^^^^^^^^^^^^^^^^^^^^^^^^^^^^^^^^^^^^^^^^^^^^
  File "D:\Projects\Stock_Market_Predictor_ETE\env\Lib\site-packages\box\box.py", line 524, in __getitem__
    raise BoxKeyError(str(err)) from _exception_cause(err)
box.exceptions.BoxKeyError: "'target_column'"

During handling of the above exception, another exception occurred:

Traceback (most recent call last):
  File "D:\Projects\Stock_Market_Predictor_ETE\env\Lib\site-packages\box\box.py", line 538, in __getattr__
    value = object.__getattribute__(self, item)
            ^^^^^^^^^^^^^^^^^^^^^^^^^^^^^^^^^^^
AttributeError: 'ConfigBox' object has no attribute 'target_column'

The above exception was the direct cause of the following exception:

Traceback (most recent call last):
  File "D:\Projects\Stock_Market_Predictor_ETE\main.py", line 47, in <module>
    obj.main()
  File "D:\Projects\Stock_Market_Predictor_ETE\src\stock_predictor\pipeline\stage_04_model_trainer.py", line 15, in main
    model_training_config = config.get_model_trainer_config()
                            ^^^^^^^^^^^^^^^^^^^^^^^^^^^^^^^^^
  File "D:\Projects\Stock_Market_Predictor_ETE\src\stock_predictor\config\configuration.py", line 62, in get_model_trainer_config
    schema = self.schema.TARGET_COLUMN
             ^^^^^^^^^^^^^^^^^^^^^^^^^
  File "D:\Projects\Stock_Market_Predictor_ETE\env\Lib\site-packages\box\config_box.py", line 30, in __getattr__
    return super().__getattr__(item.lower())
           ^^^^^^^^^^^^^^^^^^^^^^^^^^^^^^^^^
  File "D:\Projects\Stock_Market_Predictor_ETE\env\Lib\site-packages\box\box.py", line 552, in __getattr__
    raise BoxKeyError(str(err)) from _exception_cause(err)
box.exceptions.BoxKeyError: "'ConfigBox' object has no attribute 'target_column'"
[2024-05-21 10:15:08,160: INFO: main: >>>>>> stage Data Ingestion stage started <<<<<<]
[2024-05-21 10:15:08,162: INFO: common: yaml file: config\config.yaml loaded successfully]
[2024-05-21 10:15:08,162: INFO: common: yaml file: params.yaml loaded successfully]
[2024-05-21 10:15:08,163: INFO: common: yaml file: schema.yaml loaded successfully]
[2024-05-21 10:15:08,164: INFO: common: created directory at: artifacts]
[2024-05-21 10:15:08,164: INFO: common: created directory at: artifacts/data_ingestion]
[2024-05-21 10:15:08,164: INFO: data_ingestion: file already exists of size: ~ 294 KB]
[2024-05-21 10:15:08,171: INFO: main: >>>>>> stage Data Ingestion stage completed <<<<<<

x==========x]
[2024-05-21 10:15:08,171: INFO: main: >>>>>> stage Data Validation stage started <<<<<<]
[2024-05-21 10:15:08,172: INFO: common: yaml file: config\config.yaml loaded successfully]
[2024-05-21 10:15:08,173: INFO: common: yaml file: params.yaml loaded successfully]
[2024-05-21 10:15:08,174: INFO: common: yaml file: schema.yaml loaded successfully]
[2024-05-21 10:15:08,175: INFO: common: created directory at: artifacts]
[2024-05-21 10:15:08,175: INFO: common: created directory at: artifacts/data_validation]
[2024-05-21 10:15:08,194: INFO: main: >>>>>> stage Data Validation stage completed <<<<<<

x==========x]
[2024-05-21 10:15:08,194: INFO: main: >>>>>> stage Data Transformation stage started <<<<<<]
[2024-05-21 10:15:08,196: INFO: common: yaml file: config\config.yaml loaded successfully]
[2024-05-21 10:15:08,197: INFO: common: yaml file: params.yaml loaded successfully]
[2024-05-21 10:15:08,198: INFO: common: yaml file: schema.yaml loaded successfully]
[2024-05-21 10:15:08,199: INFO: common: created directory at: artifacts]
[2024-05-21 10:15:08,199: INFO: common: created directory at: artifacts/data_transformation]
[2024-05-21 10:15:08,381: INFO: data_transformation: Splitted data into training and test sets]
[2024-05-21 10:15:08,381: INFO: data_transformation: (12225, 8)]
[2024-05-21 10:15:08,381: INFO: data_transformation: (4075, 8)]
[2024-05-21 10:15:08,382: INFO: main: >>>>>> stage Data Transformation stage completed <<<<<<

x==========x]
[2024-05-21 10:15:08,382: INFO: main: >>>>>> stage Model Trainer stage started <<<<<<]
[2024-05-21 10:15:08,383: INFO: common: yaml file: config\config.yaml loaded successfully]
[2024-05-21 10:15:08,384: INFO: common: yaml file: params.yaml loaded successfully]
[2024-05-21 10:15:08,385: INFO: common: yaml file: schema.yaml loaded successfully]
[2024-05-21 10:15:08,386: INFO: common: created directory at: artifacts]
[2024-05-21 10:15:08,386: INFO: common: created directory at: artifacts/model_trainer]
[2024-05-21 10:15:08,412: ERROR: main: The 'max_depth' parameter of RandomForestRegressor must be an int in the range [1, inf) or None. Got 10.0 instead.]
Traceback (most recent call last):
  File "D:\Projects\Stock_Market_Predictor_ETE\main.py", line 47, in <module>
    obj.main()
  File "D:\Projects\Stock_Market_Predictor_ETE\src\stock_predictor\pipeline\stage_04_model_trainer.py", line 17, in main
    model_training.training()
  File "D:\Projects\Stock_Market_Predictor_ETE\src\stock_predictor\components\model_trainer.py", line 23, in training
    lr_model.fit(train_x, train_y)
  File "D:\Projects\Stock_Market_Predictor_ETE\env\Lib\site-packages\sklearn\base.py", line 1467, in wrapper
    estimator._validate_params()
  File "D:\Projects\Stock_Market_Predictor_ETE\env\Lib\site-packages\sklearn\base.py", line 666, in _validate_params
    validate_parameter_constraints(
  File "D:\Projects\Stock_Market_Predictor_ETE\env\Lib\site-packages\sklearn\utils\_param_validation.py", line 95, in validate_parameter_constraints
    raise InvalidParameterError(
sklearn.utils._param_validation.InvalidParameterError: The 'max_depth' parameter of RandomForestRegressor must be an int in the range [1, inf) or None. Got 10.0 instead.
[2024-05-21 10:15:42,425: INFO: main: >>>>>> stage Data Ingestion stage started <<<<<<]
[2024-05-21 10:15:42,427: INFO: common: yaml file: config\config.yaml loaded successfully]
[2024-05-21 10:15:42,428: INFO: common: yaml file: params.yaml loaded successfully]
[2024-05-21 10:15:42,429: INFO: common: yaml file: schema.yaml loaded successfully]
[2024-05-21 10:15:42,429: INFO: common: created directory at: artifacts]
[2024-05-21 10:15:42,430: INFO: common: created directory at: artifacts/data_ingestion]
[2024-05-21 10:15:42,430: INFO: data_ingestion: file already exists of size: ~ 294 KB]
[2024-05-21 10:15:42,437: INFO: main: >>>>>> stage Data Ingestion stage completed <<<<<<

x==========x]
[2024-05-21 10:15:42,437: INFO: main: >>>>>> stage Data Validation stage started <<<<<<]
[2024-05-21 10:15:42,438: INFO: common: yaml file: config\config.yaml loaded successfully]
[2024-05-21 10:15:42,439: INFO: common: yaml file: params.yaml loaded successfully]
[2024-05-21 10:15:42,439: INFO: common: yaml file: schema.yaml loaded successfully]
[2024-05-21 10:15:42,440: INFO: common: created directory at: artifacts]
[2024-05-21 10:15:42,440: INFO: common: created directory at: artifacts/data_validation]
[2024-05-21 10:15:42,457: INFO: main: >>>>>> stage Data Validation stage completed <<<<<<

x==========x]
[2024-05-21 10:15:42,459: INFO: main: >>>>>> stage Data Transformation stage started <<<<<<]
[2024-05-21 10:15:42,460: INFO: common: yaml file: config\config.yaml loaded successfully]
[2024-05-21 10:15:42,461: INFO: common: yaml file: params.yaml loaded successfully]
[2024-05-21 10:15:42,462: INFO: common: yaml file: schema.yaml loaded successfully]
[2024-05-21 10:15:42,463: INFO: common: created directory at: artifacts]
[2024-05-21 10:15:42,463: INFO: common: created directory at: artifacts/data_transformation]
[2024-05-21 10:15:42,647: INFO: data_transformation: Splitted data into training and test sets]
[2024-05-21 10:15:42,647: INFO: data_transformation: (12225, 8)]
[2024-05-21 10:15:42,647: INFO: data_transformation: (4075, 8)]
[2024-05-21 10:15:42,648: INFO: main: >>>>>> stage Data Transformation stage completed <<<<<<

x==========x]
[2024-05-21 10:15:42,648: INFO: main: >>>>>> stage Model Trainer stage started <<<<<<]
[2024-05-21 10:15:42,649: INFO: common: yaml file: config\config.yaml loaded successfully]
[2024-05-21 10:15:42,650: INFO: common: yaml file: params.yaml loaded successfully]
[2024-05-21 10:15:42,651: INFO: common: yaml file: schema.yaml loaded successfully]
[2024-05-21 10:15:42,651: INFO: common: created directory at: artifacts]
[2024-05-21 10:15:42,652: INFO: common: created directory at: artifacts/model_trainer]
[2024-05-21 10:15:42,675: ERROR: main: could not convert string to float: '1989-11-02']
Traceback (most recent call last):
  File "D:\Projects\Stock_Market_Predictor_ETE\main.py", line 47, in <module>
    obj.main()
  File "D:\Projects\Stock_Market_Predictor_ETE\src\stock_predictor\pipeline\stage_04_model_trainer.py", line 17, in main
    model_training.training()
  File "D:\Projects\Stock_Market_Predictor_ETE\src\stock_predictor\components\model_trainer.py", line 23, in training
    lr_model.fit(train_x, train_y)
  File "D:\Projects\Stock_Market_Predictor_ETE\env\Lib\site-packages\sklearn\base.py", line 1474, in wrapper
    return fit_method(estimator, *args, **kwargs)
           ^^^^^^^^^^^^^^^^^^^^^^^^^^^^^^^^^^^^^^
  File "D:\Projects\Stock_Market_Predictor_ETE\env\Lib\site-packages\sklearn\ensemble\_forest.py", line 363, in fit
    X, y = self._validate_data(
           ^^^^^^^^^^^^^^^^^^^^
  File "D:\Projects\Stock_Market_Predictor_ETE\env\Lib\site-packages\sklearn\base.py", line 650, in _validate_data
    X, y = check_X_y(X, y, **check_params)
           ^^^^^^^^^^^^^^^^^^^^^^^^^^^^^^^
  File "D:\Projects\Stock_Market_Predictor_ETE\env\Lib\site-packages\sklearn\utils\validation.py", line 1263, in check_X_y
    X = check_array(
        ^^^^^^^^^^^^
  File "D:\Projects\Stock_Market_Predictor_ETE\env\Lib\site-packages\sklearn\utils\validation.py", line 997, in check_array
    array = _asarray_with_order(array, order=order, dtype=dtype, xp=xp)
            ^^^^^^^^^^^^^^^^^^^^^^^^^^^^^^^^^^^^^^^^^^^^^^^^^^^^^^^^^^^
  File "D:\Projects\Stock_Market_Predictor_ETE\env\Lib\site-packages\sklearn\utils\_array_api.py", line 521, in _asarray_with_order
    array = numpy.asarray(array, order=order, dtype=dtype)
            ^^^^^^^^^^^^^^^^^^^^^^^^^^^^^^^^^^^^^^^^^^^^^^
  File "D:\Projects\Stock_Market_Predictor_ETE\env\Lib\site-packages\pandas\core\generic.py", line 2153, in __array__
    arr = np.asarray(values, dtype=dtype)
          ^^^^^^^^^^^^^^^^^^^^^^^^^^^^^^^
ValueError: could not convert string to float: '1989-11-02'
[2024-05-21 13:54:13,508: INFO: main: >>>>>> stage Data Ingestion stage started <<<<<<]
[2024-05-21 13:54:13,510: INFO: common: yaml file: config\config.yaml loaded successfully]
[2024-05-21 13:54:13,511: INFO: common: yaml file: params.yaml loaded successfully]
[2024-05-21 13:54:13,512: INFO: common: yaml file: schema.yaml loaded successfully]
[2024-05-21 13:54:13,513: INFO: common: created directory at: artifacts]
[2024-05-21 13:54:13,513: INFO: common: created directory at: artifacts/data_ingestion]
[2024-05-21 13:54:13,513: INFO: data_ingestion: file already exists of size: ~ 294 KB]
[2024-05-21 13:54:13,522: INFO: main: >>>>>> stage Data Ingestion stage completed <<<<<<

x==========x]
[2024-05-21 13:54:13,522: INFO: main: >>>>>> stage Data Validation stage started <<<<<<]
[2024-05-21 13:54:13,523: INFO: common: yaml file: config\config.yaml loaded successfully]
[2024-05-21 13:54:13,524: INFO: common: yaml file: params.yaml loaded successfully]
[2024-05-21 13:54:13,525: INFO: common: yaml file: schema.yaml loaded successfully]
[2024-05-21 13:54:13,525: INFO: common: created directory at: artifacts]
[2024-05-21 13:54:13,526: INFO: common: created directory at: artifacts/data_validation]
[2024-05-21 13:54:13,547: INFO: main: >>>>>> stage Data Validation stage completed <<<<<<

x==========x]
[2024-05-21 13:54:13,547: INFO: main: >>>>>> stage Data Transformation stage started <<<<<<]
[2024-05-21 13:54:13,549: INFO: common: yaml file: config\config.yaml loaded successfully]
[2024-05-21 13:54:13,550: INFO: common: yaml file: params.yaml loaded successfully]
[2024-05-21 13:54:13,551: INFO: common: yaml file: schema.yaml loaded successfully]
[2024-05-21 13:54:13,552: INFO: common: created directory at: artifacts]
[2024-05-21 13:54:13,552: INFO: common: created directory at: artifacts/data_transformation]
[2024-05-21 13:54:13,763: INFO: data_transformation: Splitted data into training and test sets]
[2024-05-21 13:54:13,764: INFO: data_transformation: (12225, 8)]
[2024-05-21 13:54:13,764: INFO: data_transformation: (4075, 8)]
[2024-05-21 13:54:13,765: INFO: main: >>>>>> stage Data Transformation stage completed <<<<<<

x==========x]
[2024-05-21 13:54:13,765: INFO: main: >>>>>> stage Model Trainer stage started <<<<<<]
[2024-05-21 13:54:13,767: INFO: common: yaml file: config\config.yaml loaded successfully]
[2024-05-21 13:54:13,768: INFO: common: yaml file: params.yaml loaded successfully]
[2024-05-21 13:54:13,769: INFO: common: yaml file: schema.yaml loaded successfully]
[2024-05-21 13:54:13,769: INFO: common: created directory at: artifacts]
[2024-05-21 13:54:13,770: INFO: common: created directory at: artifacts/model_trainer]
[2024-05-21 13:54:13,800: ERROR: main: could not convert string to float: '2016-06-30']
Traceback (most recent call last):
  File "D:\Projects\Stock_Market_Predictor_ETE\main.py", line 47, in <module>
    obj.main()
  File "D:\Projects\Stock_Market_Predictor_ETE\src\stock_predictor\pipeline\stage_04_model_trainer.py", line 17, in main
    model_training.training()
  File "D:\Projects\Stock_Market_Predictor_ETE\src\stock_predictor\components\model_trainer.py", line 23, in training
    lr_model.fit(train_x, train_y)
  File "D:\Projects\Stock_Market_Predictor_ETE\env\Lib\site-packages\sklearn\base.py", line 1474, in wrapper
    return fit_method(estimator, *args, **kwargs)
           ^^^^^^^^^^^^^^^^^^^^^^^^^^^^^^^^^^^^^^
  File "D:\Projects\Stock_Market_Predictor_ETE\env\Lib\site-packages\sklearn\ensemble\_forest.py", line 363, in fit
    X, y = self._validate_data(
           ^^^^^^^^^^^^^^^^^^^^
  File "D:\Projects\Stock_Market_Predictor_ETE\env\Lib\site-packages\sklearn\base.py", line 650, in _validate_data
    X, y = check_X_y(X, y, **check_params)
           ^^^^^^^^^^^^^^^^^^^^^^^^^^^^^^^
  File "D:\Projects\Stock_Market_Predictor_ETE\env\Lib\site-packages\sklearn\utils\validation.py", line 1263, in check_X_y
    X = check_array(
        ^^^^^^^^^^^^
  File "D:\Projects\Stock_Market_Predictor_ETE\env\Lib\site-packages\sklearn\utils\validation.py", line 997, in check_array
    array = _asarray_with_order(array, order=order, dtype=dtype, xp=xp)
            ^^^^^^^^^^^^^^^^^^^^^^^^^^^^^^^^^^^^^^^^^^^^^^^^^^^^^^^^^^^
  File "D:\Projects\Stock_Market_Predictor_ETE\env\Lib\site-packages\sklearn\utils\_array_api.py", line 521, in _asarray_with_order
    array = numpy.asarray(array, order=order, dtype=dtype)
            ^^^^^^^^^^^^^^^^^^^^^^^^^^^^^^^^^^^^^^^^^^^^^^
  File "D:\Projects\Stock_Market_Predictor_ETE\env\Lib\site-packages\pandas\core\generic.py", line 2153, in __array__
    arr = np.asarray(values, dtype=dtype)
          ^^^^^^^^^^^^^^^^^^^^^^^^^^^^^^^
ValueError: could not convert string to float: '2016-06-30'
[2024-05-21 14:10:04,657: INFO: main: >>>>>> stage Data Ingestion stage started <<<<<<]
[2024-05-21 14:10:04,658: INFO: common: yaml file: config\config.yaml loaded successfully]
[2024-05-21 14:10:04,659: INFO: common: yaml file: params.yaml loaded successfully]
[2024-05-21 14:10:04,661: INFO: common: yaml file: schema.yaml loaded successfully]
[2024-05-21 14:10:04,661: INFO: common: created directory at: artifacts]
[2024-05-21 14:10:04,662: INFO: common: created directory at: artifacts/data_ingestion]
[2024-05-21 14:10:04,662: INFO: data_ingestion: file already exists of size: ~ 294 KB]
[2024-05-21 14:10:04,668: INFO: main: >>>>>> stage Data Ingestion stage completed <<<<<<

x==========x]
[2024-05-21 14:10:04,668: INFO: main: >>>>>> stage Data Validation stage started <<<<<<]
[2024-05-21 14:10:04,670: INFO: common: yaml file: config\config.yaml loaded successfully]
[2024-05-21 14:10:04,670: INFO: common: yaml file: params.yaml loaded successfully]
[2024-05-21 14:10:04,671: INFO: common: yaml file: schema.yaml loaded successfully]
[2024-05-21 14:10:04,671: INFO: common: created directory at: artifacts]
[2024-05-21 14:10:04,672: INFO: common: created directory at: artifacts/data_validation]
[2024-05-21 14:10:04,690: INFO: main: >>>>>> stage Data Validation stage completed <<<<<<

x==========x]
[2024-05-21 14:10:04,691: INFO: main: >>>>>> stage Data Transformation stage started <<<<<<]
[2024-05-21 14:10:04,692: INFO: common: yaml file: config\config.yaml loaded successfully]
[2024-05-21 14:10:04,692: INFO: common: yaml file: params.yaml loaded successfully]
[2024-05-21 14:10:04,694: INFO: common: yaml file: schema.yaml loaded successfully]
[2024-05-21 14:10:04,694: INFO: common: created directory at: artifacts]
[2024-05-21 14:10:04,695: INFO: common: created directory at: artifacts/data_transformation]
[2024-05-21 14:10:04,893: INFO: data_transformation: Splitted data into training and test sets]
[2024-05-21 14:10:04,894: INFO: data_transformation: (12225, 8)]
[2024-05-21 14:10:04,894: INFO: data_transformation: (4075, 8)]
[2024-05-21 14:10:04,895: INFO: main: >>>>>> stage Data Transformation stage completed <<<<<<

x==========x]
[2024-05-21 14:10:04,895: INFO: main: >>>>>> stage Model Trainer stage started <<<<<<]
[2024-05-21 14:10:04,897: INFO: common: yaml file: config\config.yaml loaded successfully]
[2024-05-21 14:10:04,897: INFO: common: yaml file: params.yaml loaded successfully]
[2024-05-21 14:10:04,898: INFO: common: yaml file: schema.yaml loaded successfully]
[2024-05-21 14:10:04,900: INFO: common: created directory at: artifacts]
[2024-05-21 14:10:04,900: INFO: common: created directory at: artifacts/model_trainer]
[2024-05-21 14:10:04,933: ERROR: main: could not convert string to float: '2004-05-12']
Traceback (most recent call last):
  File "D:\Projects\Stock_Market_Predictor_ETE\main.py", line 47, in <module>
    obj.main()
  File "D:\Projects\Stock_Market_Predictor_ETE\src\stock_predictor\pipeline\stage_04_model_trainer.py", line 17, in main
    model_training.training()
  File "D:\Projects\Stock_Market_Predictor_ETE\src\stock_predictor\components\model_trainer.py", line 23, in training
    lr_model.fit(train_x, train_y)
  File "D:\Projects\Stock_Market_Predictor_ETE\env\Lib\site-packages\sklearn\base.py", line 1474, in wrapper
    return fit_method(estimator, *args, **kwargs)
           ^^^^^^^^^^^^^^^^^^^^^^^^^^^^^^^^^^^^^^
  File "D:\Projects\Stock_Market_Predictor_ETE\env\Lib\site-packages\sklearn\ensemble\_forest.py", line 363, in fit
    X, y = self._validate_data(
           ^^^^^^^^^^^^^^^^^^^^
  File "D:\Projects\Stock_Market_Predictor_ETE\env\Lib\site-packages\sklearn\base.py", line 650, in _validate_data
    X, y = check_X_y(X, y, **check_params)
           ^^^^^^^^^^^^^^^^^^^^^^^^^^^^^^^
  File "D:\Projects\Stock_Market_Predictor_ETE\env\Lib\site-packages\sklearn\utils\validation.py", line 1263, in check_X_y
    X = check_array(
        ^^^^^^^^^^^^
  File "D:\Projects\Stock_Market_Predictor_ETE\env\Lib\site-packages\sklearn\utils\validation.py", line 997, in check_array
    array = _asarray_with_order(array, order=order, dtype=dtype, xp=xp)
            ^^^^^^^^^^^^^^^^^^^^^^^^^^^^^^^^^^^^^^^^^^^^^^^^^^^^^^^^^^^
  File "D:\Projects\Stock_Market_Predictor_ETE\env\Lib\site-packages\sklearn\utils\_array_api.py", line 521, in _asarray_with_order
    array = numpy.asarray(array, order=order, dtype=dtype)
            ^^^^^^^^^^^^^^^^^^^^^^^^^^^^^^^^^^^^^^^^^^^^^^
  File "D:\Projects\Stock_Market_Predictor_ETE\env\Lib\site-packages\pandas\core\generic.py", line 2153, in __array__
    arr = np.asarray(values, dtype=dtype)
          ^^^^^^^^^^^^^^^^^^^^^^^^^^^^^^^
ValueError: could not convert string to float: '2004-05-12'
[2024-05-21 14:11:23,548: INFO: main: >>>>>> stage Data Ingestion stage started <<<<<<]
[2024-05-21 14:11:23,550: INFO: common: yaml file: config\config.yaml loaded successfully]
[2024-05-21 14:11:23,551: INFO: common: yaml file: params.yaml loaded successfully]
[2024-05-21 14:11:23,552: INFO: common: yaml file: schema.yaml loaded successfully]
[2024-05-21 14:11:23,552: INFO: common: created directory at: artifacts]
[2024-05-21 14:11:23,552: INFO: common: created directory at: artifacts/data_ingestion]
[2024-05-21 14:11:23,554: INFO: data_ingestion: file already exists of size: ~ 294 KB]
[2024-05-21 14:11:23,560: INFO: main: >>>>>> stage Data Ingestion stage completed <<<<<<

x==========x]
[2024-05-21 14:11:23,561: INFO: main: >>>>>> stage Data Validation stage started <<<<<<]
[2024-05-21 14:11:23,562: INFO: common: yaml file: config\config.yaml loaded successfully]
[2024-05-21 14:11:23,563: INFO: common: yaml file: params.yaml loaded successfully]
[2024-05-21 14:11:23,563: INFO: common: yaml file: schema.yaml loaded successfully]
[2024-05-21 14:11:23,564: INFO: common: created directory at: artifacts]
[2024-05-21 14:11:23,564: INFO: common: created directory at: artifacts/data_validation]
[2024-05-21 14:11:23,582: INFO: main: >>>>>> stage Data Validation stage completed <<<<<<

x==========x]
[2024-05-21 14:11:23,583: INFO: main: >>>>>> stage Data Transformation stage started <<<<<<]
[2024-05-21 14:11:23,584: INFO: common: yaml file: config\config.yaml loaded successfully]
[2024-05-21 14:11:23,585: INFO: common: yaml file: params.yaml loaded successfully]
[2024-05-21 14:11:23,586: INFO: common: yaml file: schema.yaml loaded successfully]
[2024-05-21 14:11:23,586: INFO: common: created directory at: artifacts]
[2024-05-21 14:11:23,587: INFO: common: created directory at: artifacts/data_transformation]
[2024-05-21 14:11:23,792: INFO: data_transformation: Splitted data into training and test sets]
[2024-05-21 14:11:23,794: INFO: data_transformation: (12225, 8)]
[2024-05-21 14:11:23,794: INFO: data_transformation: (4075, 8)]
[2024-05-21 14:11:23,795: INFO: main: >>>>>> stage Data Transformation stage completed <<<<<<

x==========x]
[2024-05-21 14:11:23,795: INFO: main: >>>>>> stage Model Trainer stage started <<<<<<]
[2024-05-21 14:11:23,797: INFO: common: yaml file: config\config.yaml loaded successfully]
[2024-05-21 14:11:23,798: INFO: common: yaml file: params.yaml loaded successfully]
[2024-05-21 14:11:23,799: INFO: common: yaml file: schema.yaml loaded successfully]
[2024-05-21 14:11:23,799: INFO: common: created directory at: artifacts]
[2024-05-21 14:11:23,799: INFO: common: created directory at: artifacts/model_trainer]
[2024-05-21 14:11:23,825: ERROR: main: could not convert string to float: '1996-07-03']
Traceback (most recent call last):
  File "D:\Projects\Stock_Market_Predictor_ETE\main.py", line 47, in <module>
    obj.main()
  File "D:\Projects\Stock_Market_Predictor_ETE\src\stock_predictor\pipeline\stage_04_model_trainer.py", line 17, in main
    model_training.training()
  File "D:\Projects\Stock_Market_Predictor_ETE\src\stock_predictor\components\model_trainer.py", line 23, in training
    lr_model.fit(train_x, train_y)
  File "D:\Projects\Stock_Market_Predictor_ETE\env\Lib\site-packages\sklearn\base.py", line 1474, in wrapper
    return fit_method(estimator, *args, **kwargs)
           ^^^^^^^^^^^^^^^^^^^^^^^^^^^^^^^^^^^^^^
  File "D:\Projects\Stock_Market_Predictor_ETE\env\Lib\site-packages\sklearn\ensemble\_forest.py", line 363, in fit
    X, y = self._validate_data(
           ^^^^^^^^^^^^^^^^^^^^
  File "D:\Projects\Stock_Market_Predictor_ETE\env\Lib\site-packages\sklearn\base.py", line 650, in _validate_data
    X, y = check_X_y(X, y, **check_params)
           ^^^^^^^^^^^^^^^^^^^^^^^^^^^^^^^
  File "D:\Projects\Stock_Market_Predictor_ETE\env\Lib\site-packages\sklearn\utils\validation.py", line 1263, in check_X_y
    X = check_array(
        ^^^^^^^^^^^^
  File "D:\Projects\Stock_Market_Predictor_ETE\env\Lib\site-packages\sklearn\utils\validation.py", line 997, in check_array
    array = _asarray_with_order(array, order=order, dtype=dtype, xp=xp)
            ^^^^^^^^^^^^^^^^^^^^^^^^^^^^^^^^^^^^^^^^^^^^^^^^^^^^^^^^^^^
  File "D:\Projects\Stock_Market_Predictor_ETE\env\Lib\site-packages\sklearn\utils\_array_api.py", line 521, in _asarray_with_order
    array = numpy.asarray(array, order=order, dtype=dtype)
            ^^^^^^^^^^^^^^^^^^^^^^^^^^^^^^^^^^^^^^^^^^^^^^
  File "D:\Projects\Stock_Market_Predictor_ETE\env\Lib\site-packages\pandas\core\generic.py", line 2153, in __array__
    arr = np.asarray(values, dtype=dtype)
          ^^^^^^^^^^^^^^^^^^^^^^^^^^^^^^^
ValueError: could not convert string to float: '1996-07-03'
[2024-05-21 14:12:56,184: INFO: main: >>>>>> stage Data Ingestion stage started <<<<<<]
[2024-05-21 14:12:56,186: INFO: common: yaml file: config\config.yaml loaded successfully]
[2024-05-21 14:12:56,187: INFO: common: yaml file: params.yaml loaded successfully]
[2024-05-21 14:12:56,188: INFO: common: yaml file: schema.yaml loaded successfully]
[2024-05-21 14:12:56,188: INFO: common: created directory at: artifacts]
[2024-05-21 14:12:56,188: INFO: common: created directory at: artifacts/data_ingestion]
[2024-05-21 14:12:56,189: INFO: data_ingestion: file already exists of size: ~ 294 KB]
[2024-05-21 14:12:56,196: INFO: main: >>>>>> stage Data Ingestion stage completed <<<<<<

x==========x]
[2024-05-21 14:12:56,196: INFO: main: >>>>>> stage Data Validation stage started <<<<<<]
[2024-05-21 14:12:56,197: INFO: common: yaml file: config\config.yaml loaded successfully]
[2024-05-21 14:12:56,198: INFO: common: yaml file: params.yaml loaded successfully]
[2024-05-21 14:12:56,199: INFO: common: yaml file: schema.yaml loaded successfully]
[2024-05-21 14:12:56,199: INFO: common: created directory at: artifacts]
[2024-05-21 14:12:56,199: INFO: common: created directory at: artifacts/data_validation]
[2024-05-21 14:12:56,217: INFO: main: >>>>>> stage Data Validation stage completed <<<<<<

x==========x]
[2024-05-21 14:12:56,217: INFO: main: >>>>>> stage Data Transformation stage started <<<<<<]
[2024-05-21 14:12:56,218: INFO: common: yaml file: config\config.yaml loaded successfully]
[2024-05-21 14:12:56,219: INFO: common: yaml file: params.yaml loaded successfully]
[2024-05-21 14:12:56,220: INFO: common: yaml file: schema.yaml loaded successfully]
[2024-05-21 14:12:56,220: INFO: common: created directory at: artifacts]
[2024-05-21 14:12:56,221: INFO: common: created directory at: artifacts/data_transformation]
[2024-05-21 14:12:56,425: INFO: data_transformation: Splitted data into training and test sets]
[2024-05-21 14:12:56,426: INFO: data_transformation: (12225, 8)]
[2024-05-21 14:12:56,426: INFO: data_transformation: (4075, 8)]
[2024-05-21 14:12:56,427: INFO: main: >>>>>> stage Data Transformation stage completed <<<<<<

x==========x]
[2024-05-21 14:12:56,427: INFO: main: >>>>>> stage Model Trainer stage started <<<<<<]
[2024-05-21 14:12:56,429: INFO: common: yaml file: config\config.yaml loaded successfully]
[2024-05-21 14:12:56,430: INFO: common: yaml file: params.yaml loaded successfully]
[2024-05-21 14:12:56,430: INFO: common: yaml file: schema.yaml loaded successfully]
[2024-05-21 14:12:56,431: INFO: common: created directory at: artifacts]
[2024-05-21 14:12:56,431: INFO: common: created directory at: artifacts/model_trainer]
[2024-05-21 14:12:56,455: ERROR: main: could not convert string to float: '1986-01-23']
Traceback (most recent call last):
  File "D:\Projects\Stock_Market_Predictor_ETE\main.py", line 47, in <module>
    obj.main()
  File "D:\Projects\Stock_Market_Predictor_ETE\src\stock_predictor\pipeline\stage_04_model_trainer.py", line 17, in main
    model_training.training()
  File "D:\Projects\Stock_Market_Predictor_ETE\src\stock_predictor\components\model_trainer.py", line 23, in training
    lr_model.fit(train_x, train_y)
  File "D:\Projects\Stock_Market_Predictor_ETE\env\Lib\site-packages\sklearn\base.py", line 1474, in wrapper
    return fit_method(estimator, *args, **kwargs)
           ^^^^^^^^^^^^^^^^^^^^^^^^^^^^^^^^^^^^^^
  File "D:\Projects\Stock_Market_Predictor_ETE\env\Lib\site-packages\sklearn\ensemble\_forest.py", line 363, in fit
    X, y = self._validate_data(
           ^^^^^^^^^^^^^^^^^^^^
  File "D:\Projects\Stock_Market_Predictor_ETE\env\Lib\site-packages\sklearn\base.py", line 650, in _validate_data
    X, y = check_X_y(X, y, **check_params)
           ^^^^^^^^^^^^^^^^^^^^^^^^^^^^^^^
  File "D:\Projects\Stock_Market_Predictor_ETE\env\Lib\site-packages\sklearn\utils\validation.py", line 1263, in check_X_y
    X = check_array(
        ^^^^^^^^^^^^
  File "D:\Projects\Stock_Market_Predictor_ETE\env\Lib\site-packages\sklearn\utils\validation.py", line 997, in check_array
    array = _asarray_with_order(array, order=order, dtype=dtype, xp=xp)
            ^^^^^^^^^^^^^^^^^^^^^^^^^^^^^^^^^^^^^^^^^^^^^^^^^^^^^^^^^^^
  File "D:\Projects\Stock_Market_Predictor_ETE\env\Lib\site-packages\sklearn\utils\_array_api.py", line 521, in _asarray_with_order
    array = numpy.asarray(array, order=order, dtype=dtype)
            ^^^^^^^^^^^^^^^^^^^^^^^^^^^^^^^^^^^^^^^^^^^^^^
  File "D:\Projects\Stock_Market_Predictor_ETE\env\Lib\site-packages\pandas\core\generic.py", line 2153, in __array__
    arr = np.asarray(values, dtype=dtype)
          ^^^^^^^^^^^^^^^^^^^^^^^^^^^^^^^
ValueError: could not convert string to float: '1986-01-23'
[2024-05-21 14:15:36,947: INFO: main: >>>>>> stage Data Ingestion stage started <<<<<<]
[2024-05-21 14:15:36,949: INFO: common: yaml file: config\config.yaml loaded successfully]
[2024-05-21 14:15:36,950: INFO: common: yaml file: params.yaml loaded successfully]
[2024-05-21 14:15:36,951: INFO: common: yaml file: schema.yaml loaded successfully]
[2024-05-21 14:15:36,952: INFO: common: created directory at: artifacts]
[2024-05-21 14:15:36,952: INFO: common: created directory at: artifacts/data_ingestion]
[2024-05-21 14:15:36,952: INFO: data_ingestion: file already exists of size: ~ 294 KB]
[2024-05-21 14:15:36,959: INFO: main: >>>>>> stage Data Ingestion stage completed <<<<<<

x==========x]
[2024-05-21 14:15:36,959: INFO: main: >>>>>> stage Data Validation stage started <<<<<<]
[2024-05-21 14:15:36,961: INFO: common: yaml file: config\config.yaml loaded successfully]
[2024-05-21 14:15:36,962: INFO: common: yaml file: params.yaml loaded successfully]
[2024-05-21 14:15:36,962: INFO: common: yaml file: schema.yaml loaded successfully]
[2024-05-21 14:15:36,962: INFO: common: created directory at: artifacts]
[2024-05-21 14:15:36,964: INFO: common: created directory at: artifacts/data_validation]
[2024-05-21 14:15:36,983: INFO: main: >>>>>> stage Data Validation stage completed <<<<<<

x==========x]
[2024-05-21 14:15:36,983: INFO: main: >>>>>> stage Data Transformation stage started <<<<<<]
[2024-05-21 14:15:36,984: INFO: common: yaml file: config\config.yaml loaded successfully]
[2024-05-21 14:15:36,985: INFO: common: yaml file: params.yaml loaded successfully]
[2024-05-21 14:15:36,986: INFO: common: yaml file: schema.yaml loaded successfully]
[2024-05-21 14:15:36,987: INFO: common: created directory at: artifacts]
[2024-05-21 14:15:36,987: INFO: common: created directory at: artifacts/data_transformation]
[2024-05-21 14:15:37,195: INFO: data_transformation: Splitted data into training and test sets]
[2024-05-21 14:15:37,196: INFO: data_transformation: (12225, 8)]
[2024-05-21 14:15:37,196: INFO: data_transformation: (4075, 8)]
[2024-05-21 14:15:37,196: INFO: main: >>>>>> stage Data Transformation stage completed <<<<<<

x==========x]
[2024-05-21 14:15:37,197: INFO: main: >>>>>> stage Model Trainer stage started <<<<<<]
[2024-05-21 14:15:37,198: INFO: common: yaml file: config\config.yaml loaded successfully]
[2024-05-21 14:15:37,198: INFO: common: yaml file: params.yaml loaded successfully]
[2024-05-21 14:15:37,199: INFO: common: yaml file: schema.yaml loaded successfully]
[2024-05-21 14:15:37,199: INFO: common: created directory at: artifacts]
[2024-05-21 14:15:37,200: INFO: common: created directory at: artifacts/model_trainer]
[2024-05-21 14:15:41,273: INFO: main: >>>>>> stage Model Trainer stage completed <<<<<<

x==========x]
[2024-05-21 14:40:09,204: INFO: main: >>>>>> stage Data Ingestion stage started <<<<<<]
[2024-05-21 14:40:09,205: INFO: common: yaml file: config\config.yaml loaded successfully]
[2024-05-21 14:40:09,206: INFO: common: yaml file: params.yaml loaded successfully]
[2024-05-21 14:40:09,207: INFO: common: yaml file: schema.yaml loaded successfully]
[2024-05-21 14:40:09,207: INFO: common: created directory at: artifacts]
[2024-05-21 14:40:09,207: INFO: common: created directory at: artifacts/data_ingestion]
[2024-05-21 14:40:10,614: INFO: data_ingestion: artifacts/data_ingestion/data.zip download! with following info: 
Connection: close
Content-Length: 300940
Cache-Control: max-age=300
Content-Security-Policy: default-src 'none'; style-src 'unsafe-inline'; sandbox
Content-Type: application/zip
ETag: "d076672f1746d4eb167a00b3b2c7f6458cc7ecfa4fa23f72f3f26faa16aaae43"
Strict-Transport-Security: max-age=31536000
X-Content-Type-Options: nosniff
X-Frame-Options: deny
X-XSS-Protection: 1; mode=block
X-GitHub-Request-Id: 5904:14FBEE:2668D9:33D91F:664C64F1
Accept-Ranges: bytes
Date: Tue, 21 May 2024 09:10:10 GMT
Via: 1.1 varnish
X-Served-By: cache-maa10243-MAA
X-Cache: MISS
X-Cache-Hits: 0
X-Timer: S1716282610.941991,VS0,VE309
Vary: Authorization,Accept-Encoding,Origin
Access-Control-Allow-Origin: *
Cross-Origin-Resource-Policy: cross-origin
X-Fastly-Request-ID: d31acbe1bcf555d744a2dd6b3b530e8919445fce
Expires: Tue, 21 May 2024 09:15:10 GMT
Source-Age: 0

]
[2024-05-21 14:40:10,621: INFO: main: >>>>>> stage Data Ingestion stage completed <<<<<<

x==========x]
[2024-05-21 14:40:10,621: INFO: main: >>>>>> stage Data Validation stage started <<<<<<]
[2024-05-21 14:40:10,623: INFO: common: yaml file: config\config.yaml loaded successfully]
[2024-05-21 14:40:10,624: INFO: common: yaml file: params.yaml loaded successfully]
[2024-05-21 14:40:10,625: INFO: common: yaml file: schema.yaml loaded successfully]
[2024-05-21 14:40:10,625: INFO: common: created directory at: artifacts]
[2024-05-21 14:40:10,626: INFO: common: created directory at: artifacts/data_validation]
[2024-05-21 14:40:10,642: INFO: main: >>>>>> stage Data Validation stage completed <<<<<<

x==========x]
[2024-05-21 14:40:10,642: INFO: main: >>>>>> stage Data Transformation stage started <<<<<<]
[2024-05-21 14:40:10,644: INFO: common: yaml file: config\config.yaml loaded successfully]
[2024-05-21 14:40:10,644: INFO: common: yaml file: params.yaml loaded successfully]
[2024-05-21 14:40:10,645: INFO: common: yaml file: schema.yaml loaded successfully]
[2024-05-21 14:40:10,646: INFO: common: created directory at: artifacts]
[2024-05-21 14:40:10,646: INFO: common: created directory at: artifacts/data_transformation]
[2024-05-21 14:40:10,841: INFO: data_transformation: Splitted data into training and test sets]
[2024-05-21 14:40:10,841: INFO: data_transformation: (12225, 8)]
[2024-05-21 14:40:10,841: INFO: data_transformation: (4075, 8)]
[2024-05-21 14:40:10,842: INFO: main: >>>>>> stage Data Transformation stage completed <<<<<<

x==========x]
[2024-05-21 14:40:10,843: INFO: main: >>>>>> stage Model Trainer stage started <<<<<<]
[2024-05-21 14:40:10,844: INFO: common: yaml file: config\config.yaml loaded successfully]
[2024-05-21 14:40:10,845: INFO: common: yaml file: params.yaml loaded successfully]
[2024-05-21 14:40:10,846: INFO: common: yaml file: schema.yaml loaded successfully]
[2024-05-21 14:40:10,846: INFO: common: created directory at: artifacts]
[2024-05-21 14:40:10,847: INFO: common: created directory at: artifacts/model_trainer]
[2024-05-21 14:40:14,885: INFO: main: >>>>>> stage Model Trainer stage completed <<<<<<

x==========x]
[2024-05-21 14:40:14,886: INFO: main: >>>>>> stage Model Evaluation stage started <<<<<<]
[2024-05-21 14:40:14,888: INFO: common: yaml file: config\config.yaml loaded successfully]
[2024-05-21 14:40:14,888: INFO: common: yaml file: params.yaml loaded successfully]
[2024-05-21 14:40:14,889: INFO: common: yaml file: schema.yaml loaded successfully]
[2024-05-21 14:40:14,889: INFO: common: created directory at: artifacts]
[2024-05-21 14:40:14,889: ERROR: main: "'ConfigBox' object has no attribute 'elasticnet'"]
Traceback (most recent call last):
  File "D:\Projects\Stock_Market_Predictor_ETE\env\Lib\site-packages\box\box.py", line 503, in __getitem__
    return super().__getitem__(item)
           ^^^^^^^^^^^^^^^^^^^^^^^^^
KeyError: 'ElasticNet'

The above exception was the direct cause of the following exception:

Traceback (most recent call last):
  File "D:\Projects\Stock_Market_Predictor_ETE\env\Lib\site-packages\box\box.py", line 536, in __getattr__
    value = self.__getitem__(item, _ignore_default=True)
            ^^^^^^^^^^^^^^^^^^^^^^^^^^^^^^^^^^^^^^^^^^^^
  File "D:\Projects\Stock_Market_Predictor_ETE\env\Lib\site-packages\box\box.py", line 524, in __getitem__
    raise BoxKeyError(str(err)) from _exception_cause(err)
box.exceptions.BoxKeyError: "'ElasticNet'"

During handling of the above exception, another exception occurred:

Traceback (most recent call last):
  File "D:\Projects\Stock_Market_Predictor_ETE\env\Lib\site-packages\box\box.py", line 538, in __getattr__
    value = object.__getattribute__(self, item)
            ^^^^^^^^^^^^^^^^^^^^^^^^^^^^^^^^^^^
AttributeError: 'ConfigBox' object has no attribute 'ElasticNet'

The above exception was the direct cause of the following exception:

Traceback (most recent call last):
  File "D:\Projects\Stock_Market_Predictor_ETE\env\Lib\site-packages\box\config_box.py", line 28, in __getattr__
    return super().__getattr__(item)
           ^^^^^^^^^^^^^^^^^^^^^^^^^
  File "D:\Projects\Stock_Market_Predictor_ETE\env\Lib\site-packages\box\box.py", line 552, in __getattr__
    raise BoxKeyError(str(err)) from _exception_cause(err)
box.exceptions.BoxKeyError: "'ConfigBox' object has no attribute 'ElasticNet'"

During handling of the above exception, another exception occurred:

Traceback (most recent call last):
  File "D:\Projects\Stock_Market_Predictor_ETE\env\Lib\site-packages\box\box.py", line 503, in __getitem__
    return super().__getitem__(item)
           ^^^^^^^^^^^^^^^^^^^^^^^^^
KeyError: 'elasticnet'

The above exception was the direct cause of the following exception:

Traceback (most recent call last):
  File "D:\Projects\Stock_Market_Predictor_ETE\env\Lib\site-packages\box\box.py", line 536, in __getattr__
    value = self.__getitem__(item, _ignore_default=True)
            ^^^^^^^^^^^^^^^^^^^^^^^^^^^^^^^^^^^^^^^^^^^^
  File "D:\Projects\Stock_Market_Predictor_ETE\env\Lib\site-packages\box\box.py", line 524, in __getitem__
    raise BoxKeyError(str(err)) from _exception_cause(err)
box.exceptions.BoxKeyError: "'elasticnet'"

During handling of the above exception, another exception occurred:

Traceback (most recent call last):
  File "D:\Projects\Stock_Market_Predictor_ETE\env\Lib\site-packages\box\box.py", line 538, in __getattr__
    value = object.__getattribute__(self, item)
            ^^^^^^^^^^^^^^^^^^^^^^^^^^^^^^^^^^^
AttributeError: 'ConfigBox' object has no attribute 'elasticnet'

The above exception was the direct cause of the following exception:

Traceback (most recent call last):
  File "D:\Projects\Stock_Market_Predictor_ETE\main.py", line 59, in <module>
    obj.main()
  File "D:\Projects\Stock_Market_Predictor_ETE\src\stock_predictor\pipeline\stage_05_model_evaluation.py", line 15, in main
    model_training_config = config.get_model_evaluation_config()
                            ^^^^^^^^^^^^^^^^^^^^^^^^^^^^^^^^^^^^
  File "D:\Projects\Stock_Market_Predictor_ETE\src\stock_predictor\config\configuration.py", line 80, in get_model_evaluation_config
    params = self.params.ElasticNet
             ^^^^^^^^^^^^^^^^^^^^^^
  File "D:\Projects\Stock_Market_Predictor_ETE\env\Lib\site-packages\box\config_box.py", line 30, in __getattr__
    return super().__getattr__(item.lower())
           ^^^^^^^^^^^^^^^^^^^^^^^^^^^^^^^^^
  File "D:\Projects\Stock_Market_Predictor_ETE\env\Lib\site-packages\box\box.py", line 552, in __getattr__
    raise BoxKeyError(str(err)) from _exception_cause(err)
box.exceptions.BoxKeyError: "'ConfigBox' object has no attribute 'elasticnet'"
[2024-05-21 14:41:31,383: INFO: main: >>>>>> stage Data Ingestion stage started <<<<<<]
[2024-05-21 14:41:31,385: INFO: common: yaml file: config\config.yaml loaded successfully]
[2024-05-21 14:41:31,385: INFO: common: yaml file: params.yaml loaded successfully]
[2024-05-21 14:41:31,386: INFO: common: yaml file: schema.yaml loaded successfully]
[2024-05-21 14:41:31,387: INFO: common: created directory at: artifacts]
[2024-05-21 14:41:31,387: INFO: common: created directory at: artifacts/data_ingestion]
[2024-05-21 14:41:32,178: INFO: data_ingestion: artifacts/data_ingestion/data.zip download! with following info: 
Connection: close
Content-Length: 300940
Cache-Control: max-age=300
Content-Security-Policy: default-src 'none'; style-src 'unsafe-inline'; sandbox
Content-Type: application/zip
ETag: "d076672f1746d4eb167a00b3b2c7f6458cc7ecfa4fa23f72f3f26faa16aaae43"
Strict-Transport-Security: max-age=31536000
X-Content-Type-Options: nosniff
X-Frame-Options: deny
X-XSS-Protection: 1; mode=block
X-GitHub-Request-Id: 5904:14FBEE:2668D9:33D91F:664C64F1
Accept-Ranges: bytes
Date: Tue, 21 May 2024 09:11:31 GMT
Via: 1.1 varnish
X-Served-By: cache-maa10238-MAA
X-Cache: HIT
X-Cache-Hits: 0
X-Timer: S1716282692.781413,VS0,VE1
Vary: Authorization,Accept-Encoding,Origin
Access-Control-Allow-Origin: *
Cross-Origin-Resource-Policy: cross-origin
X-Fastly-Request-ID: c2ede709bcdcadee16bbb75817f28250c70e3bdd
Expires: Tue, 21 May 2024 09:16:31 GMT
Source-Age: 82

]
[2024-05-21 14:41:32,185: INFO: main: >>>>>> stage Data Ingestion stage completed <<<<<<

x==========x]
[2024-05-21 14:41:32,185: INFO: main: >>>>>> stage Data Validation stage started <<<<<<]
[2024-05-21 14:41:32,187: INFO: common: yaml file: config\config.yaml loaded successfully]
[2024-05-21 14:41:32,187: INFO: common: yaml file: params.yaml loaded successfully]
[2024-05-21 14:41:32,188: INFO: common: yaml file: schema.yaml loaded successfully]
[2024-05-21 14:41:32,189: INFO: common: created directory at: artifacts]
[2024-05-21 14:41:32,189: INFO: common: created directory at: artifacts/data_validation]
[2024-05-21 14:41:32,209: INFO: main: >>>>>> stage Data Validation stage completed <<<<<<

x==========x]
[2024-05-21 14:41:32,209: INFO: main: >>>>>> stage Data Transformation stage started <<<<<<]
[2024-05-21 14:41:32,211: INFO: common: yaml file: config\config.yaml loaded successfully]
[2024-05-21 14:41:32,211: INFO: common: yaml file: params.yaml loaded successfully]
[2024-05-21 14:41:32,212: INFO: common: yaml file: schema.yaml loaded successfully]
[2024-05-21 14:41:32,212: INFO: common: created directory at: artifacts]
[2024-05-21 14:41:32,213: INFO: common: created directory at: artifacts/data_transformation]
[2024-05-21 14:41:32,415: INFO: data_transformation: Splitted data into training and test sets]
[2024-05-21 14:41:32,415: INFO: data_transformation: (12225, 8)]
[2024-05-21 14:41:32,417: INFO: data_transformation: (4075, 8)]
[2024-05-21 14:41:32,417: INFO: main: >>>>>> stage Data Transformation stage completed <<<<<<

x==========x]
[2024-05-21 14:41:32,417: INFO: main: >>>>>> stage Model Trainer stage started <<<<<<]
[2024-05-21 14:41:32,419: INFO: common: yaml file: config\config.yaml loaded successfully]
[2024-05-21 14:41:32,419: INFO: common: yaml file: params.yaml loaded successfully]
[2024-05-21 14:41:32,420: INFO: common: yaml file: schema.yaml loaded successfully]
[2024-05-21 14:41:32,421: INFO: common: created directory at: artifacts]
[2024-05-21 14:41:32,421: INFO: common: created directory at: artifacts/model_trainer]
[2024-05-21 14:41:36,431: INFO: main: >>>>>> stage Model Trainer stage completed <<<<<<

x==========x]
[2024-05-21 14:41:36,432: INFO: main: >>>>>> stage Model Evaluation stage started <<<<<<]
[2024-05-21 14:41:36,434: INFO: common: yaml file: config\config.yaml loaded successfully]
[2024-05-21 14:41:36,435: INFO: common: yaml file: params.yaml loaded successfully]
[2024-05-21 14:41:36,436: INFO: common: yaml file: schema.yaml loaded successfully]
[2024-05-21 14:41:36,436: INFO: common: created directory at: artifacts]
[2024-05-21 14:41:36,436: INFO: common: created directory at: artifacts/model_evaluation]
[2024-05-21 14:41:37,814: INFO: common: json file saved at: artifacts\model_evaluation\metrices.json]
[2024-05-21 14:43:35,251: INFO: main: >>>>>> stage Model Evaluation stage completed <<<<<<

x==========x]
[2024-05-21 14:46:25,513: INFO: main: >>>>>> stage Data Ingestion stage started <<<<<<]
[2024-05-21 14:46:25,515: INFO: common: yaml file: config\config.yaml loaded successfully]
[2024-05-21 14:46:25,516: INFO: common: yaml file: params.yaml loaded successfully]
[2024-05-21 14:46:25,516: INFO: common: yaml file: schema.yaml loaded successfully]
[2024-05-21 14:46:25,517: INFO: common: created directory at: artifacts]
[2024-05-21 14:46:25,517: INFO: common: created directory at: artifacts/data_ingestion]
[2024-05-21 14:46:25,517: INFO: data_ingestion: file already exists of size: ~ 294 KB]
[2024-05-21 14:46:25,524: INFO: main: >>>>>> stage Data Ingestion stage completed <<<<<<

x==========x]
[2024-05-21 14:46:25,524: INFO: main: >>>>>> stage Data Validation stage started <<<<<<]
[2024-05-21 14:46:25,525: INFO: common: yaml file: config\config.yaml loaded successfully]
[2024-05-21 14:46:25,526: INFO: common: yaml file: params.yaml loaded successfully]
[2024-05-21 14:46:25,526: INFO: common: yaml file: schema.yaml loaded successfully]
[2024-05-21 14:46:25,527: INFO: common: created directory at: artifacts]
[2024-05-21 14:46:25,527: INFO: common: created directory at: artifacts/data_validation]
[2024-05-21 14:46:25,546: INFO: main: >>>>>> stage Data Validation stage completed <<<<<<

x==========x]
[2024-05-21 14:46:25,546: INFO: main: >>>>>> stage Data Transformation stage started <<<<<<]
[2024-05-21 14:46:25,548: INFO: common: yaml file: config\config.yaml loaded successfully]
[2024-05-21 14:46:25,548: INFO: common: yaml file: params.yaml loaded successfully]
[2024-05-21 14:46:25,549: INFO: common: yaml file: schema.yaml loaded successfully]
[2024-05-21 14:46:25,550: INFO: common: created directory at: artifacts]
[2024-05-21 14:46:25,550: INFO: common: created directory at: artifacts/data_transformation]
[2024-05-21 14:46:25,743: INFO: data_transformation: Splitted data into training and test sets]
[2024-05-21 14:46:25,744: INFO: data_transformation: (12225, 8)]
[2024-05-21 14:46:25,744: INFO: data_transformation: (4075, 8)]
[2024-05-21 14:46:25,744: INFO: main: >>>>>> stage Data Transformation stage completed <<<<<<

x==========x]
[2024-05-21 14:46:25,745: INFO: main: >>>>>> stage Model Trainer stage started <<<<<<]
[2024-05-21 14:46:25,746: INFO: common: yaml file: config\config.yaml loaded successfully]
[2024-05-21 14:46:25,746: INFO: common: yaml file: params.yaml loaded successfully]
[2024-05-21 14:46:25,748: INFO: common: yaml file: schema.yaml loaded successfully]
[2024-05-21 14:46:25,748: INFO: common: created directory at: artifacts]
[2024-05-21 14:46:25,748: INFO: common: created directory at: artifacts/model_trainer]
[2024-05-21 14:46:27,912: INFO: main: >>>>>> stage Model Trainer stage completed <<<<<<

x==========x]
[2024-05-21 14:46:27,912: INFO: main: >>>>>> stage Model Evaluation stage started <<<<<<]
[2024-05-21 14:46:27,913: INFO: common: yaml file: config\config.yaml loaded successfully]
[2024-05-21 14:46:27,914: INFO: common: yaml file: params.yaml loaded successfully]
[2024-05-21 14:46:27,915: INFO: common: yaml file: schema.yaml loaded successfully]
[2024-05-21 14:46:27,915: INFO: common: created directory at: artifacts]
[2024-05-21 14:46:27,915: INFO: common: created directory at: artifacts/model_evaluation]
[2024-05-21 14:46:52,890: INFO: common: json file saved at: artifacts\model_evaluation\metrices.json]
[2024-05-21 14:48:28,629: INFO: main: >>>>>> stage Model Evaluation stage completed <<<<<<

x==========x]
[2024-05-21 17:18:38,765: INFO: _internal: [31m[1mWARNING: This is a development server. Do not use it in a production deployment. Use a production WSGI server instead.[0m
 * Running on all addresses (0.0.0.0)
 * Running on http://127.0.0.1:8080
 * Running on http://192.168.85.177:8080]
[2024-05-21 17:18:38,765: INFO: _internal: [33mPress CTRL+C to quit[0m]
[2024-05-21 17:18:38,767: INFO: _internal:  * Restarting with stat]
[2024-05-21 17:18:39,506: WARNING: _internal:  * Debugger is active!]
[2024-05-21 17:18:39,511: INFO: _internal:  * Debugger PIN: 289-919-193]
[2024-05-21 17:18:42,372: INFO: _internal: 127.0.0.1 - - [21/May/2024 17:18:42] "[35m[1mGET / HTTP/1.1[0m" 500 -]
[2024-05-21 17:18:42,488: INFO: _internal: 127.0.0.1 - - [21/May/2024 17:18:42] "GET /?__debugger__=yes&cmd=resource&f=debugger.js HTTP/1.1" 200 -]
[2024-05-21 17:18:42,490: INFO: _internal: 127.0.0.1 - - [21/May/2024 17:18:42] "GET /?__debugger__=yes&cmd=resource&f=style.css HTTP/1.1" 200 -]
[2024-05-21 17:18:42,563: INFO: _internal: 127.0.0.1 - - [21/May/2024 17:18:42] "GET /?__debugger__=yes&cmd=resource&f=console.png HTTP/1.1" 200 -]
[2024-05-21 17:18:42,793: INFO: _internal: 127.0.0.1 - - [21/May/2024 17:18:42] "[36mGET /?__debugger__=yes&cmd=resource&f=console.png HTTP/1.1[0m" 304 -]
[2024-05-21 17:26:06,619: INFO: _internal: [31m[1mWARNING: This is a development server. Do not use it in a production deployment. Use a production WSGI server instead.[0m
 * Running on all addresses (0.0.0.0)
 * Running on http://127.0.0.1:8080
 * Running on http://192.168.85.177:8080]
[2024-05-21 17:26:06,619: INFO: _internal: [33mPress CTRL+C to quit[0m]
[2024-05-21 17:26:06,620: INFO: _internal:  * Restarting with stat]
[2024-05-21 17:26:07,367: WARNING: _internal:  * Debugger is active!]
[2024-05-21 17:26:07,371: INFO: _internal:  * Debugger PIN: 289-919-193]
[2024-05-21 17:26:08,727: INFO: _internal: 127.0.0.1 - - [21/May/2024 17:26:08] "GET / HTTP/1.1" 200 -]
[2024-05-21 17:26:08,896: INFO: _internal: 127.0.0.1 - - [21/May/2024 17:26:08] "GET /static/js/script.js HTTP/1.1" 200 -]
[2024-05-21 17:26:08,900: INFO: _internal: 127.0.0.1 - - [21/May/2024 17:26:08] "GET /static/css2/nunito-font.css HTTP/1.1" 200 -]
[2024-05-21 17:26:08,908: INFO: _internal: 127.0.0.1 - - [21/May/2024 17:26:08] "GET /static/css/style.css HTTP/1.1" 200 -]
[2024-05-21 17:26:08,909: INFO: _internal: 127.0.0.1 - - [21/May/2024 17:26:08] "GET /static/css2/style.css HTTP/1.1" 200 -]
[2024-05-21 17:26:10,353: INFO: _internal: 127.0.0.1 - - [21/May/2024 17:26:10] "GET /static/asset/img/bull.jpg HTTP/1.1" 200 -]
[2024-05-21 17:26:10,353: INFO: _internal: 127.0.0.1 - - [21/May/2024 17:26:10] "GET /static/asset/img/form-v9.jpg HTTP/1.1" 200 -]
[2024-05-21 17:26:10,383: INFO: _internal: 127.0.0.1 - - [21/May/2024 17:26:10] "[33mGET /static/fonts/Nunito/Nunito-Bold.ttf HTTP/1.1[0m" 404 -]
[2024-05-21 17:26:10,681: INFO: _internal: 127.0.0.1 - - [21/May/2024 17:26:10] "GET /static/asset/favicon.ico HTTP/1.1" 200 -]
[2024-05-21 17:35:59,433: INFO: _internal:  * Detected change in 'D:\\Projects\\Stock_Market_Predictor_ETE\\app.py', reloading]
[2024-05-21 17:35:59,524: INFO: _internal:  * Restarting with stat]
[2024-05-21 17:42:08,188: INFO: _internal: [31m[1mWARNING: This is a development server. Do not use it in a production deployment. Use a production WSGI server instead.[0m
 * Running on all addresses (0.0.0.0)
 * Running on http://127.0.0.1:8080
 * Running on http://192.168.85.177:8080]
[2024-05-21 17:42:08,188: INFO: _internal: [33mPress CTRL+C to quit[0m]
[2024-05-21 17:42:08,190: INFO: _internal:  * Restarting with stat]
[2024-05-21 17:42:08,917: WARNING: _internal:  * Debugger is active!]
[2024-05-21 17:42:08,922: INFO: _internal:  * Debugger PIN: 289-919-193]
[2024-05-21 17:42:10,509: INFO: _internal: 127.0.0.1 - - [21/May/2024 17:42:10] "GET / HTTP/1.1" 200 -]
[2024-05-21 17:42:10,795: INFO: _internal: 127.0.0.1 - - [21/May/2024 17:42:10] "[36mGET /static/css/style.css HTTP/1.1[0m" 304 -]
[2024-05-21 17:42:10,832: INFO: _internal: 127.0.0.1 - - [21/May/2024 17:42:10] "[36mGET /static/css2/nunito-font.css HTTP/1.1[0m" 304 -]
[2024-05-21 17:42:10,845: INFO: _internal: 127.0.0.1 - - [21/May/2024 17:42:10] "[36mGET /static/css2/style.css HTTP/1.1[0m" 304 -]
[2024-05-21 17:42:10,876: INFO: _internal: 127.0.0.1 - - [21/May/2024 17:42:10] "[36mGET /static/js/script.js HTTP/1.1[0m" 304 -]
[2024-05-21 17:42:10,894: INFO: _internal: 127.0.0.1 - - [21/May/2024 17:42:10] "[36mGET /static/asset/img/bull.jpg HTTP/1.1[0m" 304 -]
[2024-05-21 17:42:10,932: INFO: _internal: 127.0.0.1 - - [21/May/2024 17:42:10] "[36mGET /static/asset/img/form-v9.jpg HTTP/1.1[0m" 304 -]
[2024-05-21 17:42:10,942: INFO: _internal: 127.0.0.1 - - [21/May/2024 17:42:10] "[33mGET /static/fonts/Nunito/Nunito-Bold.ttf HTTP/1.1[0m" 404 -]
[2024-05-21 17:42:37,522: INFO: _internal: 127.0.0.1 - - [21/May/2024 17:42:37] "POST /predict HTTP/1.1" 200 -]
[2024-05-21 17:42:37,622: INFO: _internal: 127.0.0.1 - - [21/May/2024 17:42:37] "[33mGET /favicon.ico HTTP/1.1[0m" 404 -]
